package mrcomputerghost.runicdungeons.world.gen;

import com.google.common.collect.Lists;
import mrcomputerghost.runicdungeons.loot.RunicLootTables;
import net.minecraft.block.state.IBlockState;
import net.minecraft.init.Blocks;
import net.minecraft.util.math.BlockPos;
import net.minecraft.world.World;

import java.util.Collections;
import java.util.List;
import java.util.Random;

public class GenIron extends GenDungeon {

    protected static final IBlockState IRON = Blocks.IRON_BARS.getDefaultState();

    protected static final IBlockState STONE = Blocks.STONE.getDefaultState();

    @Override
    public void gen(World world, int x, int y, int z) {
        GenIron.genIron(world, x, y, z);
    }

    public static void genIron(World world, int x, int y, int z) {
        Random random = new Random();
        BlockPos pos = new BlockPos(x, y, z);
        world.setBlockState(pos.add(0, 1, 6), RUNE_CRACKED, 2);
        world.setBlockState(pos.add(0, 1, 7), MOSSY, 2);
        world.setBlockState(pos.add(0, 1, 8), RUNE_PLAIN, 2);
        world.setBlockState(pos.add(0, 1, 9), PLAIN, 2);
        world.setBlockState(pos.add(0, 2, 5), RUNE_MOSSY, 2);
        world.setBlockState(pos.add(0, 2, 6), MOSSY, 2);
        world.setBlockState(pos.add(0, 2, 7), RUNE_PLAIN, 2);
        world.setBlockState(pos.add(0, 2, 8), PLAIN, 2);
        world.setBlockState(pos.add(0, 2, 9), RUNE_MOSSY, 2);
        world.setBlockState(pos.add(0, 2, 10), CRACKED, 2);
        world.setBlockState(pos.add(0, 3, 5), RUNIC_LAMP, 2);
        world.setBlockState(pos.add(0, 3, 6), CRACKED, 2);
        world.setBlockState(pos.add(0, 3, 7), KEY_STONE, 2);
        world.setBlockState(pos.add(0, 3, 8), KEY_STONE, 2);
        world.setBlockState(pos.add(0, 3, 9), PLAIN, 2);
        world.setBlockState(pos.add(0, 3, 10), RUNIC_LAMP, 2);
        world.setBlockState(pos.add(0, 4, 5), RUNE_PLAIN, 2);
        world.setBlockState(pos.add(0, 4, 6), RUNE_CRACKED, 2);
        world.setBlockState(pos.add(0, 4, 7), RUNE_PLAIN, 2);
        world.setBlockState(pos.add(0, 4, 8), CRACKED, 2);
        world.setBlockState(pos.add(0, 4, 9), RUNE_MOSSY, 2);
        world.setBlockState(pos.add(0, 4, 10), CRACKED, 2);
        world.setBlockState(pos.add(0, 5, 6), CRACKED, 2);
        world.setBlockState(pos.add(0, 5, 7), RUNE_PLAIN, 2);
        world.setBlockState(pos.add(0, 5, 8), CRACKED, 2);
        world.setBlockState(pos.add(0, 5, 9), CRACKED, 2);
        world.setBlockState(pos.add(1, 1, 1), CRACKED, 2);
        world.setBlockState(pos.add(1, 1, 2), MOSSY, 2);
        world.setBlockState(pos.add(1, 1, 3), RUNE_MOSSY, 2);
        world.setBlockState(pos.add(1, 1, 4), CRACKED, 2);
        world.setBlockState(pos.add(1, 1, 5), RUNE_PLAIN, 2);
        world.setBlockState(pos.add(1, 1, 6), CRACKED, 2);
        world.setBlockState(pos.add(1, 1, 7), RUNE_CRACKED, 2);
        world.setBlockState(pos.add(1, 1, 8), MOSSY, 2);
        world.setBlockState(pos.add(1, 1, 9), RUNE_CRACKED, 2);
        world.setBlockState(pos.add(1, 1, 10), RUNE_PLAIN, 2);
        world.setBlockState(pos.add(1, 1, 11), MOSSY, 2);
        world.setBlockState(pos.add(1, 1, 12), CRACKED, 2);
        world.setBlockState(pos.add(1, 1, 13), RUNE_PLAIN, 2);
        world.setBlockState(pos.add(1, 1, 14), PLAIN, 2);
        world.setBlockState(pos.add(1, 2, 1), MOSSY, 2);
        world.setBlockState(pos.add(1, 2, 2), RUNE_MOSSY, 2);
        world.setBlockState(pos.add(1, 2, 3), RUNE_CRACKED, 2);
        world.setBlockState(pos.add(1, 2, 4), RUNE_MOSSY, 2);
        world.setBlockState(pos.add(1, 2, 5), RUNE_MOSSY, 2);
        world.setBlockState(pos.add(1, 2, 10), MOSSY, 2);
        world.setBlockState(pos.add(1, 2, 11), RUNE_CRACKED, 2);
        world.setBlockState(pos.add(1, 2, 12), MOSSY, 2);
        world.setBlockState(pos.add(1, 2, 13), RUNE_PLAIN, 2);
        world.setBlockState(pos.add(1, 2, 14), CRACKED, 2);
        world.setBlockState(pos.add(1, 3, 1), RUNE_PLAIN, 2);
        world.setBlockState(pos.add(1, 3, 2), RUNE_PLAIN, 2);
        world.setBlockState(pos.add(1, 3, 3), RUNE_PLAIN, 2);
        world.setBlockState(pos.add(1, 3, 4), RUNE_PLAIN, 2);
        world.setBlockState(pos.add(1, 3, 5), RUNE_PLAIN, 2);
        world.setBlockState(pos.add(1, 3, 10), MOSSY, 2);
        world.setBlockState(pos.add(1, 3, 11), RUNE_CRACKED, 2);
        world.setBlockState(pos.add(1, 3, 12), RUNE_MOSSY, 2);
        world.setBlockState(pos.add(1, 3, 13), RUNE_CRACKED, 2);
        world.setBlockState(pos.add(1, 3, 14), RUNE_PLAIN, 2);
        world.setBlockState(pos.add(1, 4, 1), RUNE_PLAIN, 2);
        world.setBlockState(pos.add(1, 4, 2), RUNE_PLAIN, 2);
        world.setBlockState(pos.add(1, 4, 3), CRACKED, 2);
        world.setBlockState(pos.add(1, 4, 4), PLAIN, 2);
        world.setBlockState(pos.add(1, 4, 5), CRACKED, 2);
        world.setBlockState(pos.add(1, 4, 10), RUNE_CRACKED, 2);
        world.setBlockState(pos.add(1, 4, 11), CRACKED, 2);
        world.setBlockState(pos.add(1, 4, 12), CRACKED, 2);
        world.setBlockState(pos.add(1, 4, 13), MOSSY, 2);
        world.setBlockState(pos.add(1, 4, 14), RUNE_CRACKED, 2);
        world.setBlockState(pos.add(1, 5, 1), CRACKED, 2);
        world.setBlockState(pos.add(1, 5, 2), RUNE_MOSSY, 2);
        world.setBlockState(pos.add(1, 5, 3), RUNE_MOSSY, 2);
        world.setBlockState(pos.add(1, 5, 4), PLAIN, 2);
        world.setBlockState(pos.add(1, 5, 5), RUNE_PLAIN, 2);
        world.setBlockState(pos.add(1, 5, 6), MOSSY, 2);
        world.setBlockState(pos.add(1, 5, 7), PLAIN, 2);
        world.setBlockState(pos.add(1, 5, 8), RUNE_MOSSY, 2);
        world.setBlockState(pos.add(1, 5, 9), CRACKED, 2);
        world.setBlockState(pos.add(1, 5, 10), MOSSY, 2);
        world.setBlockState(pos.add(1, 5, 11), RUNE_PLAIN, 2);
        world.setBlockState(pos.add(1, 5, 12), PLAIN, 2);
        world.setBlockState(pos.add(1, 5, 13), RUNE_MOSSY, 2);
        world.setBlockState(pos.add(1, 5, 14), MOSSY, 2);
        world.setBlockState(pos.add(1, 6, 1), RUNE_MOSSY, 2);
        world.setBlockState(pos.add(1, 6, 2), RUNE_PLAIN, 2);
        world.setBlockState(pos.add(1, 6, 3), CRACKED, 2);
        world.setBlockState(pos.add(1, 6, 4), MOSSY, 2);
        world.setBlockState(pos.add(1, 6, 5), PLAIN, 2);
        world.setBlockState(pos.add(1, 6, 6), PLAIN, 2);
        world.setBlockState(pos.add(1, 6, 7), PLAIN, 2);
        world.setBlockState(pos.add(1, 6, 8), RUNE_CRACKED, 2);
        world.setBlockState(pos.add(1, 6, 9), RUNE_PLAIN, 2);
        world.setBlockState(pos.add(1, 6, 10), CRACKED, 2);
        world.setBlockState(pos.add(1, 6, 11), MOSSY, 2);
        world.setBlockState(pos.add(1, 6, 12), RUNE_PLAIN, 2);
        world.setBlockState(pos.add(1, 6, 13), CRACKED, 2);
        world.setBlockState(pos.add(1, 6, 14), PLAIN, 2);
        world.setBlockState(pos.add(1, 7, 1), RUNE_CRACKED, 2);
        world.setBlockState(pos.add(1, 7, 2), RUNE_CRACKED, 2);
        world.setBlockState(pos.add(1, 7, 3), RUNE_CRACKED, 2);
        world.setBlockState(pos.add(1, 7, 4), RUNE_PLAIN, 2);
        world.setBlockState(pos.add(1, 7, 5), RUNE_MOSSY, 2);
        world.setBlockState(pos.add(1, 7, 6), RUNE_MOSSY, 2);
        world.setBlockState(pos.add(1, 7, 7), PLAIN, 2);
        world.setBlockState(pos.add(1, 7, 8), RUNE_PLAIN, 2);
        world.setBlockState(pos.add(1, 7, 9), RUNE_MOSSY, 2);
        world.setBlockState(pos.add(1, 7, 10), RUNE_MOSSY, 2);
        world.setBlockState(pos.add(1, 7, 11), PLAIN, 2);
        world.setBlockState(pos.add(1, 7, 12), RUNE_PLAIN, 2);
        world.setBlockState(pos.add(1, 7, 13), RUNE_PLAIN, 2);
        world.setBlockState(pos.add(1, 7, 14), MOSSY, 2);
        world.setBlockState(pos.add(1, 8, 1), MOSSY, 2);
        world.setBlockState(pos.add(1, 8, 2), RUNE_PLAIN, 2);
        world.setBlockState(pos.add(1, 8, 3), RUNE_MOSSY, 2);
        world.setBlockState(pos.add(1, 8, 4), RUNE_PLAIN, 2);
        world.setBlockState(pos.add(1, 8, 5), RUNE_PLAIN, 2);
        world.setBlockState(pos.add(1, 8, 6), RUNE_MOSSY, 2);
        world.setBlockState(pos.add(1, 8, 7), MOSSY, 2);
        world.setBlockState(pos.add(1, 8, 8), CRACKED, 2);
        world.setBlockState(pos.add(1, 8, 9), RUNE_MOSSY, 2);
        world.setBlockState(pos.add(1, 8, 10), RUNE_CRACKED, 2);
        world.setBlockState(pos.add(1, 8, 11), CRACKED, 2);
        world.setBlockState(pos.add(1, 8, 12), RUNE_MOSSY, 2);
        world.setBlockState(pos.add(1, 8, 13), MOSSY, 2);
        world.setBlockState(pos.add(1, 8, 14), PLAIN, 2);
        world.setBlockState(pos.add(2, 1, 1), RUNE_CRACKED, 2);
        world.setBlockState(pos.add(2, 1, 2), RUNE_MOSSY, 2);
        world.setBlockState(pos.add(2, 1, 3), RUNE_MOSSY, 2);
        world.setBlockState(pos.add(2, 1, 4), RUNE_PLAIN, 2);
        world.setBlockState(pos.add(2, 1, 5), RUNE_MOSSY, 2);
        world.setBlockState(pos.add(2, 1, 6), RUNE_CRACKED, 2);
        world.setBlockState(pos.add(2, 1, 7), PLAIN, 2);
        world.setBlockState(pos.add(2, 1, 8), MOSSY, 2);
        world.setBlockState(pos.add(2, 1, 9), RUNE_CRACKED, 2);
        world.setBlockState(pos.add(2, 1, 10), RUNE_MOSSY, 2);
        world.setBlockState(pos.add(2, 1, 11), RUNE_MOSSY, 2);
        world.setBlockState(pos.add(2, 1, 12), RUNE_MOSSY, 2);
        world.setBlockState(pos.add(2, 1, 13), RUNE_CRACKED, 2);
        world.setBlockState(pos.add(2, 1, 14), RUNE_PLAIN, 2);
        world.setBlockState(pos.add(2, 2, 1), CRACKED, 2);
        world.setBlockState(pos.add(2, 2, 14), RUNE_MOSSY, 2);
        world.setBlockState(pos.add(2, 3, 1), CRACKED, 2);
        world.setBlockState(pos.add(2, 3, 14), MOSSY, 2);
        world.setBlockState(pos.add(2, 4, 1), PLAIN, 2);
        world.setBlockState(pos.add(2, 4, 14), CRACKED, 2);
        world.setBlockState(pos.add(2, 5, 1), MOSSY, 2);
        world.setBlockState(pos.add(2, 5, 14), CRACKED, 2);
        world.setBlockState(pos.add(2, 6, 1), RUNE_MOSSY, 2);
        world.setBlockState(pos.add(2, 6, 14), PLAIN, 2);
        world.setBlockState(pos.add(2, 7, 1), PLAIN, 2);
        world.setBlockState(pos.add(2, 7, 14), PLAIN, 2);
        world.setBlockState(pos.add(2, 8, 1), RUNE_PLAIN, 2);
        world.setBlockState(pos.add(2, 8, 2), PLAIN, 2);
        world.setBlockState(pos.add(2, 8, 3), CRACKED, 2);
        world.setBlockState(pos.add(2, 8, 4), MOSSY, 2);
        world.setBlockState(pos.add(2, 8, 5), RUNE_CRACKED, 2);
        world.setBlockState(pos.add(2, 8, 6), RUNE_MOSSY, 2);
        world.setBlockState(pos.add(2, 8, 7), MOSSY, 2);
        world.setBlockState(pos.add(2, 8, 8), RUNE_PLAIN, 2);
        world.setBlockState(pos.add(2, 8, 9), PLAIN, 2);
        world.setBlockState(pos.add(2, 8, 10), RUNE_MOSSY, 2);
        world.setBlockState(pos.add(2, 8, 11), RUNE_CRACKED, 2);
        world.setBlockState(pos.add(2, 8, 12), RUNE_CRACKED, 2);
        world.setBlockState(pos.add(2, 8, 13), RUNE_PLAIN, 2);
        world.setBlockState(pos.add(2, 8, 14), CRACKED, 2);
        world.setBlockState(pos.add(3, 1, 1), RUNE_MOSSY, 2);
        world.setBlockState(pos.add(3, 1, 2), PLAIN, 2);
        world.setBlockState(pos.add(3, 1, 3), RUNE_CRACKED, 2);
        world.setBlockState(pos.add(3, 1, 4), RUNE_MOSSY, 2);
        world.setBlockState(pos.add(3, 1, 5), PLAIN, 2);
        world.setBlockState(pos.add(3, 1, 6), RUNE_PLAIN, 2);
        world.setBlockState(pos.add(3, 1, 7), MOSSY, 2);
        world.setBlockState(pos.add(3, 1, 8), PLAIN, 2);
        world.setBlockState(pos.add(3, 1, 9), RUNE_PLAIN, 2);
        world.setBlockState(pos.add(3, 1, 10), RUNE_MOSSY, 2);
        world.setBlockState(pos.add(3, 1, 11), MOSSY, 2);
        world.setBlockState(pos.add(3, 1, 12), RUNE_MOSSY, 2);
        world.setBlockState(pos.add(3, 1, 13), PLAIN, 2);
        world.setBlockState(pos.add(3, 1, 14), RUNE_CRACKED, 2);
        world.setBlockState(pos.add(3, 2, 1), PLAIN, 2);
        world.setBlockState(pos.add(3, 2, 3), RUNIC_PILLAR, 2);
        world.setBlockState(pos.add(3, 2, 4), RUNIC_PILLAR, 2);
        world.setBlockState(pos.add(3, 2, 5), RUNIC_PILLAR, 2);
        world.setBlockState(pos.add(3, 2, 10), RUNIC_PILLAR, 2);
        world.setBlockState(pos.add(3, 2, 11), RUNIC_PILLAR, 2);
        world.setBlockState(pos.add(3, 2, 12), RUNIC_PILLAR, 2);
        world.setBlockState(pos.add(3, 2, 14), RUNE_CRACKED, 2);
        world.setBlockState(pos.add(3, 3, 1), CRACKED, 2);
        world.setBlockState(pos.add(3, 3, 3), RUNIC_PILLAR, 2);
        world.setBlockState(pos.add(3, 3, 4), IRON, 2);
        world.setBlockState(pos.add(3, 3, 5), RUNIC_PILLAR, 2);
        world.setBlockState(pos.add(3, 3, 10), RUNIC_PILLAR, 2);
        world.setBlockState(pos.add(3, 3, 11), IRON, 2);
        world.setBlockState(pos.add(3, 3, 12), RUNIC_PILLAR, 2);
        world.setBlockState(pos.add(3, 3, 14), RUNE_CRACKED, 2);
        world.setBlockState(pos.add(3, 4, 1), RUNE_MOSSY, 2);
        world.setBlockState(pos.add(3, 4, 3), RUNIC_PILLAR, 2);
        world.setBlockState(pos.add(3, 4, 4), RUNIC_PILLAR, 2);
        world.setBlockState(pos.add(3, 4, 5), RUNIC_PILLAR, 2);
        world.setBlockState(pos.add(3, 4, 10), RUNIC_PILLAR, 2);
        world.setBlockState(pos.add(3, 4, 11), RUNIC_PILLAR, 2);
        world.setBlockState(pos.add(3, 4, 12), RUNIC_PILLAR, 2);
        world.setBlockState(pos.add(3, 4, 14), RUNE_MOSSY, 2);
        world.setBlockState(pos.add(3, 5, 1), RUNE_CRACKED, 2);
        world.setBlockState(pos.add(3, 5, 3), RUNIC_PILLAR, 2);
        world.setBlockState(pos.add(3, 5, 4), MOSSY, 2);
        world.setBlockState(pos.add(3, 5, 5), RUNIC_PILLAR, 2);
        world.setBlockState(pos.add(3, 5, 10), RUNIC_PILLAR, 2);
        world.setBlockState(pos.add(3, 5, 11), CRACKED, 2);
        world.setBlockState(pos.add(3, 5, 12), RUNIC_PILLAR, 2);
        world.setBlockState(pos.add(3, 5, 14), RUNE_MOSSY, 2);
        world.setBlockState(pos.add(3, 6, 1), RUNE_CRACKED, 2);
        world.setBlockState(pos.add(3, 6, 3), RUNIC_PILLAR, 2);
        world.setBlockState(pos.add(3, 6, 4), RUNE_PLAIN, 2);
        world.setBlockState(pos.add(3, 6, 5), RUNIC_PILLAR, 2);
        world.setBlockState(pos.add(3, 6, 10), RUNIC_PILLAR, 2);
        world.setBlockState(pos.add(3, 6, 11), RUNE_CRACKED, 2);
        world.setBlockState(pos.add(3, 6, 12), RUNIC_PILLAR, 2);
        world.setBlockState(pos.add(3, 6, 14), RUNE_PLAIN, 2);
        world.setBlockState(pos.add(3, 7, 1), CRACKED, 2);
        world.setBlockState(pos.add(3, 7, 3), RUNIC_PILLAR, 2);
        world.setBlockState(pos.add(3, 7, 4), RUNIC_PILLAR, 2);
        world.setBlockState(pos.add(3, 7, 5), RUNIC_PILLAR, 2);
        world.setBlockState(pos.add(3, 7, 10), RUNIC_PILLAR, 2);
        world.setBlockState(pos.add(3, 7, 11), RUNIC_PILLAR, 2);
        world.setBlockState(pos.add(3, 7, 12), RUNIC_PILLAR, 2);
        world.setBlockState(pos.add(3, 7, 14), MOSSY, 2);
        world.setBlockState(pos.add(3, 8, 1), CRACKED, 2);
        world.setBlockState(pos.add(3, 8, 2), MOSSY, 2);
        world.setBlockState(pos.add(3, 8, 3), RUNE_PLAIN, 2);
        world.setBlockState(pos.add(3, 8, 4), PLAIN, 2);
        world.setBlockState(pos.add(3, 8, 5), CRACKED, 2);
        world.setBlockState(pos.add(3, 8, 6), RUNE_CRACKED, 2);
        world.setBlockState(pos.add(3, 8, 7), RUNE_PLAIN, 2);
        world.setBlockState(pos.add(3, 8, 8), CRACKED, 2);
        world.setBlockState(pos.add(3, 8, 9), RUNE_PLAIN, 2);
        world.setBlockState(pos.add(3, 8, 10), MOSSY, 2);
        world.setBlockState(pos.add(3, 8, 11), PLAIN, 2);
        world.setBlockState(pos.add(3, 8, 12), PLAIN, 2);
        world.setBlockState(pos.add(3, 8, 13), PLAIN, 2);
        world.setBlockState(pos.add(3, 8, 14), RUNE_MOSSY, 2);
        world.setBlockState(pos.add(4, 1, 1), RUNE_MOSSY, 2);
        world.setBlockState(pos.add(4, 1, 2), RUNE_CRACKED, 2);
        world.setBlockState(pos.add(4, 1, 3), RUNE_CRACKED, 2);
        world.setBlockState(pos.add(4, 1, 4), RUNIC_LAMP, 2);
        world.setBlockState(pos.add(4, 1, 5), PLAIN, 2);
        world.setBlockState(pos.add(4, 1, 6), RUNE_CRACKED, 2);
        world.setBlockState(pos.add(4, 1, 7), PLAIN, 2);
        world.setBlockState(pos.add(4, 1, 8), RUNE_CRACKED, 2);
        world.setBlockState(pos.add(4, 1, 9), CRACKED, 2);
        world.setBlockState(pos.add(4, 1, 10), RUNE_PLAIN, 2);
        world.setBlockState(pos.add(4, 1, 11), RUNIC_LAMP, 2);
        world.setBlockState(pos.add(4, 1, 12), RUNE_CRACKED, 2);
        world.setBlockState(pos.add(4, 1, 13), RUNE_PLAIN, 2);
        world.setBlockState(pos.add(4, 1, 14), RUNE_CRACKED, 2);
        world.setBlockState(pos.add(4, 2, 1), MOSSY, 2);
        world.setBlockState(pos.add(4, 2, 3), RUNIC_PILLAR, 2);
        world.setBlockState(pos.add(4, 2, 4), STONE, 2);
        world.setBlockState(pos.add(4, 2, 5), RUNIC_PILLAR, 2);
        world.setBlockState(pos.add(4, 2, 10), RUNIC_PILLAR, 2);
        world.setBlockState(pos.add(4, 2, 11), STONE, 2);
        world.setBlockState(pos.add(4, 2, 12), RUNIC_PILLAR, 2);
        world.setBlockState(pos.add(4, 2, 14), PLAIN, 2);
        world.setBlockState(pos.add(4, 3, 1), CRACKED, 2);
        world.setBlockState(pos.add(4, 3, 3), IRON, 2);
        world.setBlockState(pos.add(4, 3, 5), IRON, 2);
        world.setBlockState(pos.add(4, 3, 10), IRON, 2);
        world.setBlockState(pos.add(4, 3, 12), IRON, 2);
        world.setBlockState(pos.add(4, 3, 14), CRACKED, 2);
        world.setBlockState(pos.add(4, 4, 1), RUNE_PLAIN, 2);
        world.setBlockState(pos.add(4, 4, 3), RUNIC_PILLAR, 2);
        world.setBlockState(pos.add(4, 4, 4), STONE, 2);
        world.setBlockState(pos.add(4, 4, 5), RUNIC_PILLAR, 2);
        world.setBlockState(pos.add(4, 4, 10), RUNIC_PILLAR, 2);
        world.setBlockState(pos.add(4, 4, 11), STONE, 2);
        world.setBlockState(pos.add(4, 4, 12), RUNIC_PILLAR, 2);
        world.setBlockState(pos.add(4, 4, 14), CRACKED, 2);
        world.setBlockState(pos.add(4, 5, 1), CRACKED, 2);
        world.setBlockState(pos.add(4, 5, 3), RUNE_MOSSY, 2);
        world.setBlockState(pos.add(4, 5, 5), CRACKED, 2);
        world.setBlockState(pos.add(4, 5, 10), RUNE_MOSSY, 2);
        world.setBlockState(pos.add(4, 5, 12), RUNE_MOSSY, 2);
        world.setBlockState(pos.add(4, 5, 14), RUNE_MOSSY, 2);
        world.setBlockState(pos.add(4, 6, 1), CRACKED, 2);
        world.setBlockState(pos.add(4, 6, 3), RUNE_MOSSY, 2);
        world.setBlockState(pos.add(4, 6, 5), CRACKED, 2);
        world.setBlockState(pos.add(4, 6, 10), MOSSY, 2);
        world.setBlockState(pos.add(4, 6, 12), PLAIN, 2);
        world.setBlockState(pos.add(4, 6, 14), RUNE_MOSSY, 2);
        world.setBlockState(pos.add(4, 7, 1), RUNE_PLAIN, 2);
        world.setBlockState(pos.add(4, 7, 3), RUNIC_PILLAR, 2);
        world.setBlockState(pos.add(4, 7, 4), RUNIC_LAMP, 2);
        world.setBlockState(pos.add(4, 7, 5), RUNIC_PILLAR, 2);
        world.setBlockState(pos.add(4, 7, 10), RUNIC_PILLAR, 2);
        world.setBlockState(pos.add(4, 7, 11), RUNIC_LAMP, 2);
        world.setBlockState(pos.add(4, 7, 12), RUNIC_PILLAR, 2);
        world.setBlockState(pos.add(4, 7, 14), RUNE_MOSSY, 2);
        world.setBlockState(pos.add(4, 8, 1), RUNE_MOSSY, 2);
        world.setBlockState(pos.add(4, 8, 2), CRACKED, 2);
        world.setBlockState(pos.add(4, 8, 3), RUNE_MOSSY, 2);
        world.setBlockState(pos.add(4, 8, 4), PLAIN, 2);
        world.setBlockState(pos.add(4, 8, 5), RUNE_MOSSY, 2);
        world.setBlockState(pos.add(4, 8, 6), RUNE_CRACKED, 2);
        world.setBlockState(pos.add(4, 8, 7), RUNE_MOSSY, 2);
        world.setBlockState(pos.add(4, 8, 8), RUNE_PLAIN, 2);
        world.setBlockState(pos.add(4, 8, 9), RUNE_PLAIN, 2);
        world.setBlockState(pos.add(4, 8, 10), RUNE_PLAIN, 2);
        world.setBlockState(pos.add(4, 8, 11), CRACKED, 2);
        world.setBlockState(pos.add(4, 8, 12), PLAIN, 2);
        world.setBlockState(pos.add(4, 8, 13), PLAIN, 2);
        world.setBlockState(pos.add(4, 8, 14), CRACKED, 2);
        world.setBlockState(pos.add(5, 1, 1), RUNE_PLAIN, 2);
        world.setBlockState(pos.add(5, 1, 2), RUNE_CRACKED, 2);
        world.setBlockState(pos.add(5, 1, 3), PLAIN, 2);
        world.setBlockState(pos.add(5, 1, 4), RUNE_MOSSY, 2);
        world.setBlockState(pos.add(5, 1, 5), RUNE_MOSSY, 2);
        world.setBlockState(pos.add(5, 1, 6), RUNE_CRACKED, 2);
        world.setBlockState(pos.add(5, 1, 7), CRACKED, 2);
        world.setBlockState(pos.add(5, 1, 8), CRACKED, 2);
        world.setBlockState(pos.add(5, 1, 9), PLAIN, 2);
        world.setBlockState(pos.add(5, 1, 10), RUNE_MOSSY, 2);
        world.setBlockState(pos.add(5, 1, 11), PLAIN, 2);
        world.setBlockState(pos.add(5, 1, 12), RUNE_CRACKED, 2);
        world.setBlockState(pos.add(5, 1, 13), CRACKED, 2);
        world.setBlockState(pos.add(5, 1, 14), RUNE_CRACKED, 2);
        world.setBlockState(pos.add(5, 2, 0), MOSSY, 2);
        world.setBlockState(pos.add(5, 2, 1), PLAIN, 2);
        world.setBlockState(pos.add(5, 2, 3), RUNIC_PILLAR, 2);
        world.setBlockState(pos.add(5, 2, 4), RUNIC_PILLAR, 2);
        world.setBlockState(pos.add(5, 2, 5), RUNIC_PILLAR, 2);
        world.setBlockState(pos.add(5, 2, 10), RUNIC_PILLAR, 2);
        world.setBlockState(pos.add(5, 2, 11), RUNIC_PILLAR, 2);
        world.setBlockState(pos.add(5, 2, 12), RUNIC_PILLAR, 2);
        world.setBlockState(pos.add(5, 2, 14), RUNE_CRACKED, 2);
        world.setBlockState(pos.add(5, 2, 15), MOSSY, 2);
        world.setBlockState(pos.add(5, 3, 0), RUNIC_LAMP, 2);
        world.setBlockState(pos.add(5, 3, 1), RUNE_PLAIN, 2);
        world.setBlockState(pos.add(5, 3, 3), RUNIC_PILLAR, 2);
        world.setBlockState(pos.add(5, 3, 4), IRON, 2);
        world.setBlockState(pos.add(5, 3, 5), RUNIC_PILLAR, 2);
        world.setBlockState(pos.add(5, 3, 10), RUNIC_PILLAR, 2);
        world.setBlockState(pos.add(5, 3, 11), IRON, 2);
        world.setBlockState(pos.add(5, 3, 12), RUNIC_PILLAR, 2);
        world.setBlockState(pos.add(5, 3, 14), CRACKED, 2);
        world.setBlockState(pos.add(5, 3, 15), RUNIC_LAMP, 2);
        world.setBlockState(pos.add(5, 4, 0), MOSSY, 2);
        world.setBlockState(pos.add(5, 4, 1), RUNE_PLAIN, 2);
        world.setBlockState(pos.add(5, 4, 3), RUNIC_PILLAR, 2);
        world.setBlockState(pos.add(5, 4, 4), RUNIC_PILLAR, 2);
        world.setBlockState(pos.add(5, 4, 5), RUNIC_PILLAR, 2);
        world.setBlockState(pos.add(5, 4, 10), RUNIC_PILLAR, 2);
        world.setBlockState(pos.add(5, 4, 11), RUNIC_PILLAR, 2);
        world.setBlockState(pos.add(5, 4, 12), RUNIC_PILLAR, 2);
        world.setBlockState(pos.add(5, 4, 14), RUNE_CRACKED, 2);
        world.setBlockState(pos.add(5, 4, 15), CRACKED, 2);
        world.setBlockState(pos.add(5, 5, 1), RUNE_PLAIN, 2);
        world.setBlockState(pos.add(5, 5, 3), RUNIC_PILLAR, 2);
        world.setBlockState(pos.add(5, 5, 4), RUNE_CRACKED, 2);
        world.setBlockState(pos.add(5, 5, 5), RUNIC_PILLAR, 2);
        world.setBlockState(pos.add(5, 5, 10), RUNIC_PILLAR, 2);
        world.setBlockState(pos.add(5, 5, 11), RUNE_MOSSY, 2);
        world.setBlockState(pos.add(5, 5, 12), RUNIC_PILLAR, 2);
        world.setBlockState(pos.add(5, 5, 14), RUNE_MOSSY, 2);
        world.setBlockState(pos.add(5, 6, 1), MOSSY, 2);
        world.setBlockState(pos.add(5, 6, 3), RUNIC_PILLAR, 2);
        world.setBlockState(pos.add(5, 6, 4), PLAIN, 2);
        world.setBlockState(pos.add(5, 6, 5), RUNIC_PILLAR, 2);
        world.setBlockState(pos.add(5, 6, 10), RUNIC_PILLAR, 2);
        world.setBlockState(pos.add(5, 6, 11), CRACKED, 2);
        world.setBlockState(pos.add(5, 6, 12), RUNIC_PILLAR, 2);
        world.setBlockState(pos.add(5, 6, 14), PLAIN, 2);
        world.setBlockState(pos.add(5, 7, 1), MOSSY, 2);
        world.setBlockState(pos.add(5, 7, 3), RUNIC_PILLAR, 2);
        world.setBlockState(pos.add(5, 7, 4), RUNIC_PILLAR, 2);
        world.setBlockState(pos.add(5, 7, 5), RUNIC_PILLAR, 2);
        world.setBlockState(pos.add(5, 7, 10), RUNIC_PILLAR, 2);
        world.setBlockState(pos.add(5, 7, 11), RUNIC_PILLAR, 2);
        world.setBlockState(pos.add(5, 7, 12), RUNIC_PILLAR, 2);
        world.setBlockState(pos.add(5, 7, 14), CRACKED, 2);
        world.setBlockState(pos.add(5, 8, 1), RUNE_PLAIN, 2);
        world.setBlockState(pos.add(5, 8, 2), RUNE_MOSSY, 2);
        world.setBlockState(pos.add(5, 8, 3), RUNE_PLAIN, 2);
        world.setBlockState(pos.add(5, 8, 4), RUNE_CRACKED, 2);
        world.setBlockState(pos.add(5, 8, 5), PLAIN, 2);
        world.setBlockState(pos.add(5, 8, 6), RUNE_PLAIN, 2);
        world.setBlockState(pos.add(5, 8, 7), RUNE_MOSSY, 2);
        world.setBlockState(pos.add(5, 8, 8), MOSSY, 2);
        world.setBlockState(pos.add(5, 8, 9), MOSSY, 2);
        world.setBlockState(pos.add(5, 8, 10), MOSSY, 2);
        world.setBlockState(pos.add(5, 8, 11), PLAIN, 2);
        world.setBlockState(pos.add(5, 8, 12), RUNE_MOSSY, 2);
        world.setBlockState(pos.add(5, 8, 13), MOSSY, 2);
        world.setBlockState(pos.add(5, 8, 14), RUNE_MOSSY, 2);
        world.setBlockState(pos.add(6, 1, 0), RUNE_PLAIN, 2);
        world.setBlockState(pos.add(6, 1, 1), CRACKED, 2);
        world.setBlockState(pos.add(6, 1, 2), PLAIN, 2);
        world.setBlockState(pos.add(6, 1, 3), RUNE_MOSSY, 2);
        world.setBlockState(pos.add(6, 1, 4), CRACKED, 2);
        world.setBlockState(pos.add(6, 1, 5), RUNE_MOSSY, 2);
        world.setBlockState(pos.add(6, 1, 6), RUNE_PLAIN, 2);
        world.setBlockState(pos.add(6, 1, 7), RUNE_CRACKED, 2);
        world.setBlockState(pos.add(6, 1, 8), CRACKED, 2);
        world.setBlockState(pos.add(6, 1, 9), MOSSY, 2);
        world.setBlockState(pos.add(6, 1, 10), CRACKED, 2);
        world.setBlockState(pos.add(6, 1, 11), RUNE_CRACKED, 2);
        world.setBlockState(pos.add(6, 1, 12), CRACKED, 2);
        world.setBlockState(pos.add(6, 1, 13), CRACKED, 2);
        world.setBlockState(pos.add(6, 1, 14), MOSSY, 2);
        world.setBlockState(pos.add(6, 1, 15), PLAIN, 2);
        world.setBlockState(pos.add(6, 2, 0), MOSSY, 2);
        world.setBlockState(pos.add(6, 2, 15), RUNE_CRACKED, 2);
        world.setBlockState(pos.add(6, 3, 0), MOSSY, 2);
        world.setBlockState(pos.add(6, 3, 15), RUNE_PLAIN, 2);
        world.setBlockState(pos.add(6, 4, 0), RUNE_CRACKED, 2);
        world.setBlockState(pos.add(6, 4, 15), RUNE_CRACKED, 2);
        world.setBlockState(pos.add(6, 5, 0), RUNE_CRACKED, 2);
        world.setBlockState(pos.add(6, 5, 1), CRACKED, 2);
        world.setBlockState(pos.add(6, 5, 14), CRACKED, 2);
        world.setBlockState(pos.add(6, 5, 15), CRACKED, 2);
        world.setBlockState(pos.add(6, 6, 1), RUNE_CRACKED, 2);
        world.setBlockState(pos.add(6, 6, 14), PLAIN, 2);
        world.setBlockState(pos.add(6, 7, 1), CRACKED, 2);
        world.setBlockState(pos.add(6, 7, 14), PLAIN, 2);
        world.setBlockState(pos.add(6, 8, 1), CRACKED, 2);
        world.setBlockState(pos.add(6, 8, 2), PLAIN, 2);
        world.setBlockState(pos.add(6, 8, 3), PLAIN, 2);
        world.setBlockState(pos.add(6, 8, 4), RUNE_CRACKED, 2);
        world.setBlockState(pos.add(6, 8, 5), CRACKED, 2);
        world.setBlockState(pos.add(6, 8, 6), RUNE_MOSSY, 2);
        world.setBlockState(pos.add(6, 8, 7), RUNE_CRACKED, 2);
        world.setBlockState(pos.add(6, 8, 8), CRACKED, 2);
        world.setBlockState(pos.add(6, 8, 9), MOSSY, 2);
        world.setBlockState(pos.add(6, 8, 10), RUNE_PLAIN, 2);
        world.setBlockState(pos.add(6, 8, 11), CRACKED, 2);
        world.setBlockState(pos.add(6, 8, 12), RUNE_CRACKED, 2);
        world.setBlockState(pos.add(6, 8, 13), CRACKED, 2);
        world.setBlockState(pos.add(6, 8, 14), MOSSY, 2);
        world.setBlockState(pos.add(7, 1, 0), PLAIN, 2);
        world.setBlockState(pos.add(7, 1, 1), MOSSY, 2);
        world.setBlockState(pos.add(7, 1, 2), MOSSY, 2);
        world.setBlockState(pos.add(7, 1, 3), RUNE_MOSSY, 2);
        world.setBlockState(pos.add(7, 1, 4), RUNE_CRACKED, 2);
        world.setBlockState(pos.add(7, 1, 5), CRACKED, 2);
        world.setBlockState(pos.add(7, 1, 6), RUNE_CRACKED, 2);
        world.setBlockState(pos.add(7, 1, 7), PLAIN, 2);
        world.setBlockState(pos.add(7, 1, 8), RUNE_CRACKED, 2);
        world.setBlockState(pos.add(7, 1, 9), MOSSY, 2);
        world.setBlockState(pos.add(7, 1, 10), MOSSY, 2);
        world.setBlockState(pos.add(7, 1, 11), MOSSY, 2);
        world.setBlockState(pos.add(7, 1, 12), CRACKED, 2);
        world.setBlockState(pos.add(7, 1, 13), RUNE_MOSSY, 2);
        world.setBlockState(pos.add(7, 1, 14), RUNE_MOSSY, 2);
        world.setBlockState(pos.add(7, 1, 15), PLAIN, 2);
        world.setBlockState(pos.add(7, 2, 0), PLAIN, 2);
        world.setBlockState(pos.add(7, 2, 15), MOSSY, 2);
        world.setBlockState(pos.add(7, 3, 0), KEY_STONE, 2);
        world.setBlockState(pos.add(7, 3, 15), KEY_STONE, 2);
        world.setBlockState(pos.add(7, 4, 0), RUNE_CRACKED, 2);
        world.setBlockState(pos.add(7, 4, 15), RUNE_CRACKED, 2);
        world.setBlockState(pos.add(7, 5, 0), RUNE_CRACKED, 2);
        world.setBlockState(pos.add(7, 5, 1), MOSSY, 2);
        world.setBlockState(pos.add(7, 5, 14), MOSSY, 2);
        world.setBlockState(pos.add(7, 5, 15), PLAIN, 2);
        world.setBlockState(pos.add(7, 6, 1), MOSSY, 2);
        world.setBlockState(pos.add(7, 6, 14), MOSSY, 2);
        world.setBlockState(pos.add(7, 7, 1), RUNE_CRACKED, 2);
        world.setBlockState(pos.add(7, 7, 14), RUNE_MOSSY, 2);
        world.setBlockState(pos.add(7, 8, 1), PLAIN, 2);
        world.setBlockState(pos.add(7, 8, 2), RUNE_CRACKED, 2);
        world.setBlockState(pos.add(7, 8, 3), PLAIN, 2);
        world.setBlockState(pos.add(7, 8, 4), RUNE_CRACKED, 2);
        world.setBlockState(pos.add(7, 8, 5), PLAIN, 2);
        world.setBlockState(pos.add(7, 8, 6), RUNE_MOSSY, 2);
        world.setBlockState(pos.add(7, 8, 7), RUNE_PLAIN, 2);
        world.setBlockState(pos.add(7, 8, 8), CRACKED, 2);
        world.setBlockState(pos.add(7, 8, 9), CRACKED, 2);
        world.setBlockState(pos.add(7, 8, 10), RUNE_PLAIN, 2);
        world.setBlockState(pos.add(7, 8, 11), RUNE_CRACKED, 2);
        world.setBlockState(pos.add(7, 8, 12), CRACKED, 2);
        world.setBlockState(pos.add(7, 8, 13), RUNE_MOSSY, 2);
        world.setBlockState(pos.add(7, 8, 14), PLAIN, 2);
        world.setBlockState(pos.add(8, 1, 0), CRACKED, 2);
        world.setBlockState(pos.add(8, 1, 1), PLAIN, 2);
        world.setBlockState(pos.add(8, 1, 2), RUNE_MOSSY, 2);
        world.setBlockState(pos.add(8, 1, 3), MOSSY, 2);
        world.setBlockState(pos.add(8, 1, 4), CRACKED, 2);
        world.setBlockState(pos.add(8, 1, 5), CRACKED, 2);
        world.setBlockState(pos.add(8, 1, 6), PLAIN, 2);
        world.setBlockState(pos.add(8, 1, 7), RUNE_MOSSY, 2);
        world.setBlockState(pos.add(8, 1, 8), RUNE_CRACKED, 2);
        world.setBlockState(pos.add(8, 1, 9), PLAIN, 2);
        world.setBlockState(pos.add(8, 1, 10), PLAIN, 2);
        world.setBlockState(pos.add(8, 1, 11), RUNE_MOSSY, 2);
        world.setBlockState(pos.add(8, 1, 12), RUNE_MOSSY, 2);
        world.setBlockState(pos.add(8, 1, 13), RUNE_MOSSY, 2);
        world.setBlockState(pos.add(8, 1, 14), RUNE_PLAIN, 2);
        world.setBlockState(pos.add(8, 1, 15), RUNE_MOSSY, 2);
        world.setBlockState(pos.add(8, 2, 0), RUNE_MOSSY, 2);
        world.setBlockState(pos.add(8, 2, 15), MOSSY, 2);
        world.setBlockState(pos.add(8, 3, 0), KEY_STONE, 2);
        world.setBlockState(pos.add(8, 3, 15), KEY_STONE, 2);
        world.setBlockState(pos.add(8, 4, 0), RUNE_MOSSY, 2);
        world.setBlockState(pos.add(8, 4, 15), RUNE_PLAIN, 2);
        world.setBlockState(pos.add(8, 5, 0), RUNE_PLAIN, 2);
        world.setBlockState(pos.add(8, 5, 1), PLAIN, 2);
        world.setBlockState(pos.add(8, 5, 14), PLAIN, 2);
        world.setBlockState(pos.add(8, 5, 15), MOSSY, 2);
        world.setBlockState(pos.add(8, 6, 1), RUNE_MOSSY, 2);
        world.setBlockState(pos.add(8, 6, 14), RUNE_MOSSY, 2);
        world.setBlockState(pos.add(8, 7, 1), RUNE_PLAIN, 2);
        world.setBlockState(pos.add(8, 7, 14), CRACKED, 2);
        world.setBlockState(pos.add(8, 8, 1), RUNE_PLAIN, 2);
        world.setBlockState(pos.add(8, 8, 2), CRACKED, 2);
        world.setBlockState(pos.add(8, 8, 3), MOSSY, 2);
        world.setBlockState(pos.add(8, 8, 4), MOSSY, 2);
        world.setBlockState(pos.add(8, 8, 5), MOSSY, 2);
        world.setBlockState(pos.add(8, 8, 6), CRACKED, 2);
        world.setBlockState(pos.add(8, 8, 7), CRACKED, 2);
        world.setBlockState(pos.add(8, 8, 8), RUNE_CRACKED, 2);
        world.setBlockState(pos.add(8, 8, 9), PLAIN, 2);
        world.setBlockState(pos.add(8, 8, 10), RUNE_CRACKED, 2);
        world.setBlockState(pos.add(8, 8, 11), MOSSY, 2);
        world.setBlockState(pos.add(8, 8, 12), RUNE_PLAIN, 2);
        world.setBlockState(pos.add(8, 8, 13), MOSSY, 2);
        world.setBlockState(pos.add(8, 8, 14), CRACKED, 2);
        world.setBlockState(pos.add(9, 1, 0), MOSSY, 2);
        world.setBlockState(pos.add(9, 1, 1), RUNE_PLAIN, 2);
        world.setBlockState(pos.add(9, 1, 2), MOSSY, 2);
        world.setBlockState(pos.add(9, 1, 3), RUNE_MOSSY, 2);
        world.setBlockState(pos.add(9, 1, 4), RUNE_CRACKED, 2);
        world.setBlockState(pos.add(9, 1, 5), PLAIN, 2);
        world.setBlockState(pos.add(9, 1, 6), RUNE_MOSSY, 2);
        world.setBlockState(pos.add(9, 1, 7), PLAIN, 2);
        world.setBlockState(pos.add(9, 1, 8), RUNE_MOSSY, 2);
        world.setBlockState(pos.add(9, 1, 9), RUNE_CRACKED, 2);
        world.setBlockState(pos.add(9, 1, 10), RUNE_PLAIN, 2);
        world.setBlockState(pos.add(9, 1, 11), RUNE_MOSSY, 2);
        world.setBlockState(pos.add(9, 1, 12), RUNE_PLAIN, 2);
        world.setBlockState(pos.add(9, 1, 13), PLAIN, 2);
        world.setBlockState(pos.add(9, 1, 14), CRACKED, 2);
        world.setBlockState(pos.add(9, 1, 15), CRACKED, 2);
        world.setBlockState(pos.add(9, 2, 0), RUNE_MOSSY, 2);
        world.setBlockState(pos.add(9, 2, 15), RUNE_PLAIN, 2);
        world.setBlockState(pos.add(9, 3, 0), CRACKED, 2);
        world.setBlockState(pos.add(9, 3, 15), RUNE_PLAIN, 2);
        world.setBlockState(pos.add(9, 4, 0), PLAIN, 2);
        world.setBlockState(pos.add(9, 4, 15), RUNE_MOSSY, 2);
        world.setBlockState(pos.add(9, 5, 0), RUNE_CRACKED, 2);
        world.setBlockState(pos.add(9, 5, 1), PLAIN, 2);
        world.setBlockState(pos.add(9, 5, 14), RUNE_PLAIN, 2);
        world.setBlockState(pos.add(9, 5, 15), RUNE_CRACKED, 2);
        world.setBlockState(pos.add(9, 6, 1), RUNE_CRACKED, 2);
        world.setBlockState(pos.add(9, 6, 14), CRACKED, 2);
        world.setBlockState(pos.add(9, 7, 1), RUNE_MOSSY, 2);
        world.setBlockState(pos.add(9, 7, 14), CRACKED, 2);
        world.setBlockState(pos.add(9, 8, 1), PLAIN, 2);
        world.setBlockState(pos.add(9, 8, 2), PLAIN, 2);
        world.setBlockState(pos.add(9, 8, 3), MOSSY, 2);
        world.setBlockState(pos.add(9, 8, 4), CRACKED, 2);
        world.setBlockState(pos.add(9, 8, 5), RUNE_MOSSY, 2);
        world.setBlockState(pos.add(9, 8, 6), RUNE_CRACKED, 2);
        world.setBlockState(pos.add(9, 8, 7), CRACKED, 2);
        world.setBlockState(pos.add(9, 8, 8), RUNE_MOSSY, 2);
        world.setBlockState(pos.add(9, 8, 9), PLAIN, 2);
        world.setBlockState(pos.add(9, 8, 10), RUNE_PLAIN, 2);
        world.setBlockState(pos.add(9, 8, 11), CRACKED, 2);
        world.setBlockState(pos.add(9, 8, 12), MOSSY, 2);
        world.setBlockState(pos.add(9, 8, 13), RUNE_MOSSY, 2);
        world.setBlockState(pos.add(9, 8, 14), CRACKED, 2);
        world.setBlockState(pos.add(10, 1, 1), MOSSY, 2);
        world.setBlockState(pos.add(10, 1, 2), CRACKED, 2);
        world.setBlockState(pos.add(10, 1, 3), RUNE_PLAIN, 2);
        world.setBlockState(pos.add(10, 1, 4), RUNE_PLAIN, 2);
        world.setBlockState(pos.add(10, 1, 5), RUNE_PLAIN, 2);
        world.setBlockState(pos.add(10, 1, 6), MOSSY, 2);
        world.setBlockState(pos.add(10, 1, 7), RUNE_PLAIN, 2);
        world.setBlockState(pos.add(10, 1, 8), RUNE_PLAIN, 2);
        world.setBlockState(pos.add(10, 1, 9), MOSSY, 2);
        world.setBlockState(pos.add(10, 1, 10), RUNE_MOSSY, 2);
        world.setBlockState(pos.add(10, 1, 11), RUNE_PLAIN, 2);
        world.setBlockState(pos.add(10, 1, 12), PLAIN, 2);
        world.setBlockState(pos.add(10, 1, 13), CRACKED, 2);
        world.setBlockState(pos.add(10, 1, 14), RUNE_PLAIN, 2);
        world.setBlockState(pos.add(10, 2, 0), PLAIN, 2);
        world.setBlockState(pos.add(10, 2, 1), RUNE_MOSSY, 2);
        world.setBlockState(pos.add(10, 2, 3), RUNIC_PILLAR, 2);
        world.setBlockState(pos.add(10, 2, 4), RUNIC_PILLAR, 2);
        world.setBlockState(pos.add(10, 2, 5), RUNIC_PILLAR, 2);
        world.setBlockState(pos.add(10, 2, 10), RUNIC_PILLAR, 2);
        world.setBlockState(pos.add(10, 2, 11), RUNIC_PILLAR, 2);
        world.setBlockState(pos.add(10, 2, 12), RUNIC_PILLAR, 2);
        world.setBlockState(pos.add(10, 2, 14), CRACKED, 2);
        world.setBlockState(pos.add(10, 2, 15), RUNE_CRACKED, 2);
        world.setBlockState(pos.add(10, 3, 0), RUNIC_LAMP, 2);
        world.setBlockState(pos.add(10, 3, 1), CRACKED, 2);
        world.setBlockState(pos.add(10, 3, 3), RUNIC_PILLAR, 2);
        world.setBlockState(pos.add(10, 3, 4), IRON, 2);
        world.setBlockState(pos.add(10, 3, 5), RUNIC_PILLAR, 2);
        world.setBlockState(pos.add(10, 3, 10), RUNIC_PILLAR, 2);
        world.setBlockState(pos.add(10, 3, 11), IRON, 2);
        world.setBlockState(pos.add(10, 3, 12), RUNIC_PILLAR, 2);
        world.setBlockState(pos.add(10, 3, 14), RUNE_PLAIN, 2);
        world.setBlockState(pos.add(10, 3, 15), RUNIC_LAMP, 2);
        world.setBlockState(pos.add(10, 4, 0), RUNE_MOSSY, 2);
        world.setBlockState(pos.add(10, 4, 1), PLAIN, 2);
        world.setBlockState(pos.add(10, 4, 3), RUNIC_PILLAR, 2);
        world.setBlockState(pos.add(10, 4, 4), RUNIC_PILLAR, 2);
        world.setBlockState(pos.add(10, 4, 5), RUNIC_PILLAR, 2);
        world.setBlockState(pos.add(10, 4, 10), RUNIC_PILLAR, 2);
        world.setBlockState(pos.add(10, 4, 11), RUNIC_PILLAR, 2);
        world.setBlockState(pos.add(10, 4, 12), RUNIC_PILLAR, 2);
        world.setBlockState(pos.add(10, 4, 14), MOSSY, 2);
        world.setBlockState(pos.add(10, 4, 15), RUNE_MOSSY, 2);
        world.setBlockState(pos.add(10, 5, 1), CRACKED, 2);
        world.setBlockState(pos.add(10, 5, 3), RUNIC_PILLAR, 2);
        world.setBlockState(pos.add(10, 5, 4), RUNE_MOSSY, 2);
        world.setBlockState(pos.add(10, 5, 5), RUNIC_PILLAR, 2);
        world.setBlockState(pos.add(10, 5, 10), RUNIC_PILLAR, 2);
        world.setBlockState(pos.add(10, 5, 11), PLAIN, 2);
        world.setBlockState(pos.add(10, 5, 12), RUNIC_PILLAR, 2);
        world.setBlockState(pos.add(10, 5, 14), CRACKED, 2);
        world.setBlockState(pos.add(10, 6, 1), RUNE_MOSSY, 2);
        world.setBlockState(pos.add(10, 6, 3), RUNIC_PILLAR, 2);
        world.setBlockState(pos.add(10, 6, 4), PLAIN, 2);
        world.setBlockState(pos.add(10, 6, 5), RUNIC_PILLAR, 2);
        world.setBlockState(pos.add(10, 6, 10), RUNIC_PILLAR, 2);
        world.setBlockState(pos.add(10, 6, 11), RUNE_PLAIN, 2);
        world.setBlockState(pos.add(10, 6, 12), RUNIC_PILLAR, 2);
        world.setBlockState(pos.add(10, 6, 14), PLAIN, 2);
        world.setBlockState(pos.add(10, 7, 1), RUNE_MOSSY, 2);
        world.setBlockState(pos.add(10, 7, 3), RUNIC_PILLAR, 2);
        world.setBlockState(pos.add(10, 7, 4), RUNIC_PILLAR, 2);
        world.setBlockState(pos.add(10, 7, 5), RUNIC_PILLAR, 2);
        world.setBlockState(pos.add(10, 7, 10), RUNIC_PILLAR, 2);
        world.setBlockState(pos.add(10, 7, 11), RUNIC_PILLAR, 2);
        world.setBlockState(pos.add(10, 7, 12), RUNIC_PILLAR, 2);
        world.setBlockState(pos.add(10, 7, 14), RUNE_MOSSY, 2);
        world.setBlockState(pos.add(10, 8, 1), CRACKED, 2);
        world.setBlockState(pos.add(10, 8, 2), MOSSY, 2);
        world.setBlockState(pos.add(10, 8, 3), RUNE_PLAIN, 2);
        world.setBlockState(pos.add(10, 8, 4), CRACKED, 2);
        world.setBlockState(pos.add(10, 8, 5), CRACKED, 2);
        world.setBlockState(pos.add(10, 8, 6), RUNE_MOSSY, 2);
        world.setBlockState(pos.add(10, 8, 7), RUNE_PLAIN, 2);
        world.setBlockState(pos.add(10, 8, 8), PLAIN, 2);
        world.setBlockState(pos.add(10, 8, 9), RUNE_MOSSY, 2);
        world.setBlockState(pos.add(10, 8, 10), PLAIN, 2);
        world.setBlockState(pos.add(10, 8, 11), RUNE_CRACKED, 2);
        world.setBlockState(pos.add(10, 8, 12), PLAIN, 2);
        world.setBlockState(pos.add(10, 8, 13), PLAIN, 2);
        world.setBlockState(pos.add(10, 8, 14), RUNE_PLAIN, 2);
        world.setBlockState(pos.add(11, 1, 1), RUNE_CRACKED, 2);
        world.setBlockState(pos.add(11, 1, 2), PLAIN, 2);
        world.setBlockState(pos.add(11, 1, 3), RUNE_PLAIN, 2);
        world.setBlockState(pos.add(11, 1, 4), RUNIC_LAMP, 2);
        world.setBlockState(pos.add(11, 1, 5), RUNE_CRACKED, 2);
        world.setBlockState(pos.add(11, 1, 6), RUNE_PLAIN, 2);
        world.setBlockState(pos.add(11, 1, 7), MOSSY, 2);
        world.setBlockState(pos.add(11, 1, 8), RUNE_PLAIN, 2);
        world.setBlockState(pos.add(11, 1, 9), MOSSY, 2);
        world.setBlockState(pos.add(11, 1, 10), RUNE_MOSSY, 2);
        world.setBlockState(pos.add(11, 1, 11), RUNIC_LAMP, 2);
        world.setBlockState(pos.add(11, 1, 12), RUNE_MOSSY, 2);
        world.setBlockState(pos.add(11, 1, 13), CRACKED, 2);
        world.setBlockState(pos.add(11, 1, 14), RUNE_MOSSY, 2);
        world.setBlockState(pos.add(11, 2, 1), RUNE_CRACKED, 2);
        world.setBlockState(pos.add(11, 2, 3), RUNIC_PILLAR, 2);
        world.setBlockState(pos.add(11, 2, 4), STONE, 2);
        world.setBlockState(pos.add(11, 2, 5), RUNIC_PILLAR, 2);
        world.setBlockState(pos.add(11, 2, 10), RUNIC_PILLAR, 2);
        world.setBlockState(pos.add(11, 2, 11), STONE, 2);
        world.setBlockState(pos.add(11, 2, 12), RUNIC_PILLAR, 2);
        world.setBlockState(pos.add(11, 2, 14), CRACKED, 2);
        world.setBlockState(pos.add(11, 3, 1), RUNE_CRACKED, 2);
        world.setBlockState(pos.add(11, 3, 3), IRON, 2);
        world.setBlockState(pos.add(11, 3, 5), IRON, 2);
        world.setBlockState(pos.add(11, 3, 10), IRON, 2);
        world.setBlockState(pos.add(11, 3, 12), IRON, 2);
        world.setBlockState(pos.add(11, 3, 14), RUNE_MOSSY, 2);
        world.setBlockState(pos.add(11, 4, 1), RUNE_MOSSY, 2);
        world.setBlockState(pos.add(11, 4, 3), RUNIC_PILLAR, 2);
        world.setBlockState(pos.add(11, 4, 4), STONE, 2);
        world.setBlockState(pos.add(11, 4, 5), RUNIC_PILLAR, 2);
        world.setBlockState(pos.add(11, 4, 10), RUNIC_PILLAR, 2);
        world.setBlockState(pos.add(11, 4, 11), STONE, 2);
        world.setBlockState(pos.add(11, 4, 12), RUNIC_PILLAR, 2);
        world.setBlockState(pos.add(11, 4, 14), RUNE_MOSSY, 2);
        world.setBlockState(pos.add(11, 5, 1), RUNE_MOSSY, 2);
        world.setBlockState(pos.add(11, 5, 3), RUNE_MOSSY, 2);
        world.setBlockState(pos.add(11, 5, 5), RUNE_PLAIN, 2);
        world.setBlockState(pos.add(11, 5, 10), MOSSY, 2);
        world.setBlockState(pos.add(11, 5, 12), RUNE_CRACKED, 2);
        world.setBlockState(pos.add(11, 5, 14), CRACKED, 2);
        world.setBlockState(pos.add(11, 6, 1), RUNE_CRACKED, 2);
        world.setBlockState(pos.add(11, 6, 3), RUNE_CRACKED, 2);
        world.setBlockState(pos.add(11, 6, 5), CRACKED, 2);
        world.setBlockState(pos.add(11, 6, 10), CRACKED, 2);
        world.setBlockState(pos.add(11, 6, 12), RUNE_MOSSY, 2);
        world.setBlockState(pos.add(11, 6, 14), PLAIN, 2);
        world.setBlockState(pos.add(11, 7, 1), RUNE_CRACKED, 2);
        world.setBlockState(pos.add(11, 7, 3), RUNIC_PILLAR, 2);
        world.setBlockState(pos.add(11, 7, 4), RUNIC_LAMP, 2);
        world.setBlockState(pos.add(11, 7, 5), RUNIC_PILLAR, 2);
        world.setBlockState(pos.add(11, 7, 10), RUNIC_PILLAR, 2);
        world.setBlockState(pos.add(11, 7, 11), RUNIC_LAMP, 2);
        world.setBlockState(pos.add(11, 7, 12), RUNIC_PILLAR, 2);
        world.setBlockState(pos.add(11, 7, 14), PLAIN, 2);
        world.setBlockState(pos.add(11, 8, 1), MOSSY, 2);
        world.setBlockState(pos.add(11, 8, 2), RUNE_PLAIN, 2);
        world.setBlockState(pos.add(11, 8, 3), PLAIN, 2);
        world.setBlockState(pos.add(11, 8, 4), PLAIN, 2);
        world.setBlockState(pos.add(11, 8, 5), RUNE_MOSSY, 2);
        world.setBlockState(pos.add(11, 8, 6), MOSSY, 2);
        world.setBlockState(pos.add(11, 8, 7), RUNE_CRACKED, 2);
        world.setBlockState(pos.add(11, 8, 8), MOSSY, 2);
        world.setBlockState(pos.add(11, 8, 9), PLAIN, 2);
        world.setBlockState(pos.add(11, 8, 10), PLAIN, 2);
        world.setBlockState(pos.add(11, 8, 11), RUNE_MOSSY, 2);
        world.setBlockState(pos.add(11, 8, 12), PLAIN, 2);
        world.setBlockState(pos.add(11, 8, 13), CRACKED, 2);
        world.setBlockState(pos.add(11, 8, 14), RUNE_MOSSY, 2);
        world.setBlockState(pos.add(12, 1, 1), RUNE_MOSSY, 2);
        world.setBlockState(pos.add(12, 1, 2), RUNE_CRACKED, 2);
        world.setBlockState(pos.add(12, 1, 3), MOSSY, 2);
        world.setBlockState(pos.add(12, 1, 4), MOSSY, 2);
        world.setBlockState(pos.add(12, 1, 5), RUNE_PLAIN, 2);
        world.setBlockState(pos.add(12, 1, 6), RUNE_MOSSY, 2);
        world.setBlockState(pos.add(12, 1, 7), CRACKED, 2);
        world.setBlockState(pos.add(12, 1, 8), RUNE_CRACKED, 2);
        world.setBlockState(pos.add(12, 1, 9), RUNE_PLAIN, 2);
        world.setBlockState(pos.add(12, 1, 10), PLAIN, 2);
        world.setBlockState(pos.add(12, 1, 11), CRACKED, 2);
        world.setBlockState(pos.add(12, 1, 12), CRACKED, 2);
        world.setBlockState(pos.add(12, 1, 13), MOSSY, 2);
        world.setBlockState(pos.add(12, 1, 14), RUNE_CRACKED, 2);
        world.setBlockState(pos.add(12, 2, 1), PLAIN, 2);
        world.setBlockState(pos.add(12, 2, 3), RUNIC_PILLAR, 2);
        world.setBlockState(pos.add(12, 2, 4), RUNIC_PILLAR, 2);
        world.setBlockState(pos.add(12, 2, 5), RUNIC_PILLAR, 2);
        world.setBlockState(pos.add(12, 2, 10), RUNIC_PILLAR, 2);
        world.setBlockState(pos.add(12, 2, 11), RUNIC_PILLAR, 2);
        world.setBlockState(pos.add(12, 2, 12), RUNIC_PILLAR, 2);
        world.setBlockState(pos.add(12, 2, 14), PLAIN, 2);
        world.setBlockState(pos.add(12, 3, 1), MOSSY, 2);
        world.setBlockState(pos.add(12, 3, 3), RUNIC_PILLAR, 2);
        world.setBlockState(pos.add(12, 3, 4), IRON, 2);
        world.setBlockState(pos.add(12, 3, 5), RUNIC_PILLAR, 2);
        world.setBlockState(pos.add(12, 3, 10), RUNIC_PILLAR, 2);
        world.setBlockState(pos.add(12, 3, 11), IRON, 2);
        world.setBlockState(pos.add(12, 3, 12), RUNIC_PILLAR, 2);
        world.setBlockState(pos.add(12, 3, 14), RUNE_CRACKED, 2);
        world.setBlockState(pos.add(12, 4, 1), RUNE_MOSSY, 2);
        world.setBlockState(pos.add(12, 4, 3), RUNIC_PILLAR, 2);
        world.setBlockState(pos.add(12, 4, 4), RUNIC_PILLAR, 2);
        world.setBlockState(pos.add(12, 4, 5), RUNIC_PILLAR, 2);
        world.setBlockState(pos.add(12, 4, 10), RUNIC_PILLAR, 2);
        world.setBlockState(pos.add(12, 4, 11), RUNIC_PILLAR, 2);
        world.setBlockState(pos.add(12, 4, 12), RUNIC_PILLAR, 2);
        world.setBlockState(pos.add(12, 4, 14), RUNE_MOSSY, 2);
        world.setBlockState(pos.add(12, 5, 1), MOSSY, 2);
        world.setBlockState(pos.add(12, 5, 3), RUNIC_PILLAR, 2);
        world.setBlockState(pos.add(12, 5, 4), MOSSY, 2);
        world.setBlockState(pos.add(12, 5, 5), RUNIC_PILLAR, 2);
        world.setBlockState(pos.add(12, 5, 10), RUNIC_PILLAR, 2);
        world.setBlockState(pos.add(12, 5, 11), MOSSY, 2);
        world.setBlockState(pos.add(12, 5, 12), RUNIC_PILLAR, 2);
        world.setBlockState(pos.add(12, 5, 14), RUNE_CRACKED, 2);
        world.setBlockState(pos.add(12, 6, 1), RUNE_CRACKED, 2);
        world.setBlockState(pos.add(12, 6, 3), RUNIC_PILLAR, 2);
        world.setBlockState(pos.add(12, 6, 4), MOSSY, 2);
        world.setBlockState(pos.add(12, 6, 5), RUNIC_PILLAR, 2);
        world.setBlockState(pos.add(12, 6, 10), RUNIC_PILLAR, 2);
        world.setBlockState(pos.add(12, 6, 11), PLAIN, 2);
        world.setBlockState(pos.add(12, 6, 12), RUNIC_PILLAR, 2);
        world.setBlockState(pos.add(12, 6, 14), RUNE_CRACKED, 2);
        world.setBlockState(pos.add(12, 7, 1), PLAIN, 2);
        world.setBlockState(pos.add(12, 7, 3), RUNIC_PILLAR, 2);
        world.setBlockState(pos.add(12, 7, 4), RUNIC_PILLAR, 2);
        world.setBlockState(pos.add(12, 7, 5), RUNIC_PILLAR, 2);
        world.setBlockState(pos.add(12, 7, 10), RUNIC_PILLAR, 2);
        world.setBlockState(pos.add(12, 7, 11), RUNIC_PILLAR, 2);
        world.setBlockState(pos.add(12, 7, 12), RUNIC_PILLAR, 2);
        world.setBlockState(pos.add(12, 7, 14), MOSSY, 2);
        world.setBlockState(pos.add(12, 8, 1), CRACKED, 2);
        world.setBlockState(pos.add(12, 8, 2), CRACKED, 2);
        world.setBlockState(pos.add(12, 8, 3), RUNE_PLAIN, 2);
        world.setBlockState(pos.add(12, 8, 4), MOSSY, 2);
        world.setBlockState(pos.add(12, 8, 5), MOSSY, 2);
        world.setBlockState(pos.add(12, 8, 6), RUNE_PLAIN, 2);
        world.setBlockState(pos.add(12, 8, 7), RUNE_CRACKED, 2);
        world.setBlockState(pos.add(12, 8, 8), RUNE_CRACKED, 2);
        world.setBlockState(pos.add(12, 8, 9), RUNE_PLAIN, 2);
        world.setBlockState(pos.add(12, 8, 10), CRACKED, 2);
        world.setBlockState(pos.add(12, 8, 11), RUNE_PLAIN, 2);
        world.setBlockState(pos.add(12, 8, 12), PLAIN, 2);
        world.setBlockState(pos.add(12, 8, 13), MOSSY, 2);
        world.setBlockState(pos.add(12, 8, 14), CRACKED, 2);
        world.setBlockState(pos.add(13, 1, 1), RUNE_MOSSY, 2);
        world.setBlockState(pos.add(13, 1, 2), CRACKED, 2);
        world.setBlockState(pos.add(13, 1, 3), MOSSY, 2);
        world.setBlockState(pos.add(13, 1, 4), MOSSY, 2);
        world.setBlockState(pos.add(13, 1, 5), RUNE_MOSSY, 2);
        world.setBlockState(pos.add(13, 1, 6), RUNE_CRACKED, 2);
        world.setBlockState(pos.add(13, 1, 7), PLAIN, 2);
        world.setBlockState(pos.add(13, 1, 8), PLAIN, 2);
        world.setBlockState(pos.add(13, 1, 9), PLAIN, 2);
        world.setBlockState(pos.add(13, 1, 10), PLAIN, 2);
        world.setBlockState(pos.add(13, 1, 11), RUNE_PLAIN, 2);
        world.setBlockState(pos.add(13, 1, 12), CRACKED, 2);
        world.setBlockState(pos.add(13, 1, 13), RUNE_CRACKED, 2);
        world.setBlockState(pos.add(13, 1, 14), RUNE_PLAIN, 2);
        world.setBlockState(pos.add(13, 2, 1), RUNE_CRACKED, 2);
        world.setBlockState(pos.add(13, 2, 14), PLAIN, 2);
        world.setBlockState(pos.add(13, 3, 1), PLAIN, 2);
        world.setBlockState(pos.add(13, 3, 14), RUNE_CRACKED, 2);
        world.setBlockState(pos.add(13, 4, 1), RUNE_CRACKED, 2);
        world.setBlockState(pos.add(13, 4, 14), CRACKED, 2);
        world.setBlockState(pos.add(13, 5, 1), CRACKED, 2);
        world.setBlockState(pos.add(13, 5, 14), RUNE_PLAIN, 2);
        world.setBlockState(pos.add(13, 6, 1), RUNE_MOSSY, 2);
        world.setBlockState(pos.add(13, 6, 14), CRACKED, 2);
        world.setBlockState(pos.add(13, 7, 1), CRACKED, 2);
        world.setBlockState(pos.add(13, 7, 14), MOSSY, 2);
        world.setBlockState(pos.add(13, 8, 1), RUNE_CRACKED, 2);
        world.setBlockState(pos.add(13, 8, 2), CRACKED, 2);
        world.setBlockState(pos.add(13, 8, 3), PLAIN, 2);
        world.setBlockState(pos.add(13, 8, 4), RUNE_MOSSY, 2);
        world.setBlockState(pos.add(13, 8, 5), MOSSY, 2);
        world.setBlockState(pos.add(13, 8, 6), MOSSY, 2);
        world.setBlockState(pos.add(13, 8, 7), RUNE_PLAIN, 2);
        world.setBlockState(pos.add(13, 8, 8), MOSSY, 2);
        world.setBlockState(pos.add(13, 8, 9), RUNE_MOSSY, 2);
        world.setBlockState(pos.add(13, 8, 10), RUNE_MOSSY, 2);
        world.setBlockState(pos.add(13, 8, 11), PLAIN, 2);
        world.setBlockState(pos.add(13, 8, 12), CRACKED, 2);
        world.setBlockState(pos.add(13, 8, 13), RUNE_PLAIN, 2);
        world.setBlockState(pos.add(13, 8, 14), RUNE_MOSSY, 2);
        world.setBlockState(pos.add(14, 1, 1), PLAIN, 2);
        world.setBlockState(pos.add(14, 1, 2), CRACKED, 2);
        world.setBlockState(pos.add(14, 1, 3), MOSSY, 2);
        world.setBlockState(pos.add(14, 1, 4), PLAIN, 2);
        world.setBlockState(pos.add(14, 1, 5), RUNE_PLAIN, 2);
        world.setBlockState(pos.add(14, 1, 6), CRACKED, 2);
        world.setBlockState(pos.add(14, 1, 7), MOSSY, 2);
        world.setBlockState(pos.add(14, 1, 8), CRACKED, 2);
        world.setBlockState(pos.add(14, 1, 9), RUNE_CRACKED, 2);
        world.setBlockState(pos.add(14, 1, 10), PLAIN, 2);
        world.setBlockState(pos.add(14, 1, 11), MOSSY, 2);
        world.setBlockState(pos.add(14, 1, 12), CRACKED, 2);
        world.setBlockState(pos.add(14, 1, 13), RUNE_PLAIN, 2);
        world.setBlockState(pos.add(14, 1, 14), MOSSY, 2);
        world.setBlockState(pos.add(14, 2, 1), RUNE_MOSSY, 2);
        world.setBlockState(pos.add(14, 2, 2), RUNE_PLAIN, 2);
        world.setBlockState(pos.add(14, 2, 3), MOSSY, 2);
        world.setBlockState(pos.add(14, 2, 4), RUNE_CRACKED, 2);
        world.setBlockState(pos.add(14, 2, 5), MOSSY, 2);
        world.setBlockState(pos.add(14, 2, 10), CRACKED, 2);
        world.setBlockState(pos.add(14, 2, 11), MOSSY, 2);
        world.setBlockState(pos.add(14, 2, 12), RUNE_PLAIN, 2);
        world.setBlockState(pos.add(14, 2, 13), RUNE_CRACKED, 2);
        world.setBlockState(pos.add(14, 2, 14), RUNE_PLAIN, 2);
        world.setBlockState(pos.add(14, 3, 1), RUNE_PLAIN, 2);
        world.setBlockState(pos.add(14, 3, 2), RUNE_CRACKED, 2);
        world.setBlockState(pos.add(14, 3, 3), RUNE_PLAIN, 2);
        world.setBlockState(pos.add(14, 3, 4), RUNE_PLAIN, 2);
        world.setBlockState(pos.add(14, 3, 5), RUNE_MOSSY, 2);
        world.setBlockState(pos.add(14, 3, 10), CRACKED, 2);
        world.setBlockState(pos.add(14, 3, 11), CRACKED, 2);
        world.setBlockState(pos.add(14, 3, 12), RUNE_PLAIN, 2);
        world.setBlockState(pos.add(14, 3, 13), CRACKED, 2);
        world.setBlockState(pos.add(14, 3, 14), MOSSY, 2);
        world.setBlockState(pos.add(14, 4, 1), CRACKED, 2);
        world.setBlockState(pos.add(14, 4, 2), PLAIN, 2);
        world.setBlockState(pos.add(14, 4, 3), RUNE_CRACKED, 2);
        world.setBlockState(pos.add(14, 4, 4), RUNE_CRACKED, 2);
        world.setBlockState(pos.add(14, 4, 5), RUNE_CRACKED, 2);
        world.setBlockState(pos.add(14, 4, 10), MOSSY, 2);
        world.setBlockState(pos.add(14, 4, 11), RUNE_MOSSY, 2);
        world.setBlockState(pos.add(14, 4, 12), RUNE_PLAIN, 2);
        world.setBlockState(pos.add(14, 4, 13), RUNE_MOSSY, 2);
        world.setBlockState(pos.add(14, 4, 14), MOSSY, 2);
        world.setBlockState(pos.add(14, 5, 1), RUNE_CRACKED, 2);
        world.setBlockState(pos.add(14, 5, 2), RUNE_PLAIN, 2);
        world.setBlockState(pos.add(14, 5, 3), MOSSY, 2);
        world.setBlockState(pos.add(14, 5, 4), RUNE_MOSSY, 2);
        world.setBlockState(pos.add(14, 5, 5), RUNE_CRACKED, 2);
        world.setBlockState(pos.add(14, 5, 6), RUNE_MOSSY, 2);
        world.setBlockState(pos.add(14, 5, 7), CRACKED, 2);
        world.setBlockState(pos.add(14, 5, 8), RUNE_MOSSY, 2);
        world.setBlockState(pos.add(14, 5, 9), MOSSY, 2);
        world.setBlockState(pos.add(14, 5, 10), CRACKED, 2);
        world.setBlockState(pos.add(14, 5, 11), PLAIN, 2);
        world.setBlockState(pos.add(14, 5, 12), RUNE_MOSSY, 2);
        world.setBlockState(pos.add(14, 5, 13), MOSSY, 2);
        world.setBlockState(pos.add(14, 5, 14), CRACKED, 2);
        world.setBlockState(pos.add(14, 6, 1), CRACKED, 2);
        world.setBlockState(pos.add(14, 6, 2), RUNE_CRACKED, 2);
        world.setBlockState(pos.add(14, 6, 3), RUNE_MOSSY, 2);
        world.setBlockState(pos.add(14, 6, 4), RUNE_MOSSY, 2);
        world.setBlockState(pos.add(14, 6, 5), PLAIN, 2);
        world.setBlockState(pos.add(14, 6, 6), RUNE_MOSSY, 2);
        world.setBlockState(pos.add(14, 6, 7), RUNE_MOSSY, 2);
        world.setBlockState(pos.add(14, 6, 8), RUNE_MOSSY, 2);
        world.setBlockState(pos.add(14, 6, 9), RUNE_MOSSY, 2);
        world.setBlockState(pos.add(14, 6, 10), RUNE_MOSSY, 2);
        world.setBlockState(pos.add(14, 6, 11), PLAIN, 2);
        world.setBlockState(pos.add(14, 6, 12), RUNE_CRACKED, 2);
        world.setBlockState(pos.add(14, 6, 13), RUNE_PLAIN, 2);
        world.setBlockState(pos.add(14, 6, 14), CRACKED, 2);
        world.setBlockState(pos.add(14, 7, 1), MOSSY, 2);
        world.setBlockState(pos.add(14, 7, 2), RUNE_PLAIN, 2);
        world.setBlockState(pos.add(14, 7, 3), PLAIN, 2);
        world.setBlockState(pos.add(14, 7, 4), RUNE_MOSSY, 2);
        world.setBlockState(pos.add(14, 7, 5), MOSSY, 2);
        world.setBlockState(pos.add(14, 7, 6), MOSSY, 2);
        world.setBlockState(pos.add(14, 7, 7), CRACKED, 2);
        world.setBlockState(pos.add(14, 7, 8), RUNE_PLAIN, 2);
        world.setBlockState(pos.add(14, 7, 9), MOSSY, 2);
        world.setBlockState(pos.add(14, 7, 10), RUNE_CRACKED, 2);
        world.setBlockState(pos.add(14, 7, 11), PLAIN, 2);
        world.setBlockState(pos.add(14, 7, 12), RUNE_PLAIN, 2);
        world.setBlockState(pos.add(14, 7, 13), RUNE_PLAIN, 2);
        world.setBlockState(pos.add(14, 7, 14), CRACKED, 2);
        world.setBlockState(pos.add(14, 8, 1), RUNE_PLAIN, 2);
        world.setBlockState(pos.add(14, 8, 2), PLAIN, 2);
        world.setBlockState(pos.add(14, 8, 3), CRACKED, 2);
        world.setBlockState(pos.add(14, 8, 4), RUNE_PLAIN, 2);
        world.setBlockState(pos.add(14, 8, 5), RUNE_PLAIN, 2);
        world.setBlockState(pos.add(14, 8, 6), CRACKED, 2);
        world.setBlockState(pos.add(14, 8, 7), RUNE_PLAIN, 2);
        world.setBlockState(pos.add(14, 8, 8), PLAIN, 2);
        world.setBlockState(pos.add(14, 8, 9), RUNE_PLAIN, 2);
        world.setBlockState(pos.add(14, 8, 10), RUNE_CRACKED, 2);
        world.setBlockState(pos.add(14, 8, 11), CRACKED, 2);
        world.setBlockState(pos.add(14, 8, 12), RUNE_PLAIN, 2);
        world.setBlockState(pos.add(14, 8, 13), RUNE_PLAIN, 2);
        world.setBlockState(pos.add(14, 8, 14), RUNE_MOSSY, 2);
        world.setBlockState(pos.add(15, 1, 6), CRACKED, 2);
        world.setBlockState(pos.add(15, 1, 7), RUNE_MOSSY, 2);
        world.setBlockState(pos.add(15, 1, 8), RUNE_MOSSY, 2);
        world.setBlockState(pos.add(15, 1, 9), RUNE_CRACKED, 2);
        world.setBlockState(pos.add(15, 1, 10), RUNE_CRACKED, 2);
        world.setBlockState(pos.add(15, 2, 5), MOSSY, 2);
        world.setBlockState(pos.add(15, 2, 6), RUNE_PLAIN, 2);
        world.setBlockState(pos.add(15, 2, 7), RUNE_PLAIN, 2);
        world.setBlockState(pos.add(15, 2, 8), MOSSY, 2);
        world.setBlockState(pos.add(15, 2, 9), RUNE_CRACKED, 2);
        world.setBlockState(pos.add(15, 2, 10), CRACKED, 2);
        world.setBlockState(pos.add(15, 3, 5), RUNIC_LAMP, 2);
        world.setBlockState(pos.add(15, 3, 6), PLAIN, 2);
        world.setBlockState(pos.add(15, 3, 7), KEY_STONE, 2);
        world.setBlockState(pos.add(15, 3, 8), KEY_STONE, 2);
        world.setBlockState(pos.add(15, 3, 9), PLAIN, 2);
        world.setBlockState(pos.add(15, 3, 10), RUNIC_LAMP, 2);
        world.setBlockState(pos.add(15, 4, 5), PLAIN, 2);
        world.setBlockState(pos.add(15, 4, 6), CRACKED, 2);
        world.setBlockState(pos.add(15, 4, 7), RUNE_PLAIN, 2);
        world.setBlockState(pos.add(15, 4, 8), RUNE_MOSSY, 2);
        world.setBlockState(pos.add(15, 4, 9), PLAIN, 2);
        world.setBlockState(pos.add(15, 4, 10), RUNE_MOSSY, 2);
        world.setBlockState(pos.add(15, 5, 6), CRACKED, 2);
        world.setBlockState(pos.add(15, 5, 7), RUNE_CRACKED, 2);
        world.setBlockState(pos.add(15, 5, 8), PLAIN, 2);
        world.setBlockState(pos.add(15, 5, 9), CRACKED, 2);

        List<BlockPos> list = Lists.newArrayList(pos.add(4, 3, 4),
                pos.add(4, 3, 11), pos.add(11, 3, 4),
                pos.add(11, 3, 11));
        Collections.shuffle(list, random);
        generateMobSpawner(world, list.get(0));
        generateMobSpawner(world, list.get(1));
        generateDropper(world, list.get(2));
        generateChest(world, list.get(3), RunicLootTables.IRON);
    }

}