package mrcomputerghost.runicdungeons.world.gen;

import net.minecraft.util.math.BlockPos;
import net.minecraft.world.World;

/**
 * @author ji_GGO
 * @date 29/12/2020
 */
public class GenStone extends GenDungeon {

    @Override
    public void gen(World world, int x, int y, int z) {
        GenStone.genStone(world, x, y, z);
    }

    public static void genStone(World world, int x, int y, int z) {
        world.setBlockState(new BlockPos(x, y + 1, z + 6), PLAIN, 2);
        world.setBlockState(new BlockPos(x, y + 1, z + 7), MOSSY, 2);
        world.setBlockState(new BlockPos(x, y + 1, z + 8), MOSSY, 2);
        world.setBlockState(new BlockPos(x, y + 1, z + 9), CRACKED, 2);
        world.setBlockState(new BlockPos(x, y + 2, z + 5), RUNE_CRACKED, 2);
        world.setBlockState(new BlockPos(x, y + 2, z + 6), RUNE_CRACKED, 2);
        world.setBlockState(new BlockPos(x, y + 2, z + 7), RUNE_MOSSY, 2);
        world.setBlockState(new BlockPos(x, y + 2, z + 8), RUNE_CRACKED, 2);
        world.setBlockState(new BlockPos(x, y + 2, z + 9), RUNE_PLAIN, 2);
        world.setBlockState(new BlockPos(x, y + 2, z + 10), PLAIN, 2);
        world.setBlockState(new BlockPos(x, y + 3, z + 5), RUNIC_LAMP, 2);
        world.setBlockState(new BlockPos(x, y + 3, z + 6), RUNE_PLAIN, 2);
        world.setBlockState(new BlockPos(x, y + 3, z + 7), KEY_STONE, 2);
        world.setBlockState(new BlockPos(x, y + 3, z + 8), KEY_STONE, 2);
        world.setBlockState(new BlockPos(x, y + 3, z + 9), MOSSY, 2);
        world.setBlockState(new BlockPos(x, y + 3, z + 10), RUNIC_LAMP, 2);
        world.setBlockState(new BlockPos(x, y + 4, z + 5), PLAIN, 2);
        world.setBlockState(new BlockPos(x, y + 4, z + 6), PLAIN, 2);
        world.setBlockState(new BlockPos(x, y + 4, z + 7), MOSSY, 2);
        world.setBlockState(new BlockPos(x, y + 4, z + 8), MOSSY, 2);
        world.setBlockState(new BlockPos(x, y + 4, z + 9), RUNE_CRACKED, 2);
        world.setBlockState(new BlockPos(x, y + 4, z + 10), RUNE_PLAIN, 2);
        world.setBlockState(new BlockPos(x, y + 5, z + 6), RUNE_CRACKED, 2);
        world.setBlockState(new BlockPos(x, y + 5, z + 7), RUNE_PLAIN, 2);
        world.setBlockState(new BlockPos(x, y + 5, z + 8), MOSSY, 2);
        world.setBlockState(new BlockPos(x, y + 5, z + 9), CRACKED, 2);
        world.setBlockState(new BlockPos(x + 1, y + 1, z + 1), RUNE_PLAIN, 2);
        world.setBlockState(new BlockPos(x + 1, y + 1, z + 2), RUNE_MOSSY, 2);
        world.setBlockState(new BlockPos(x + 1, y + 1, z + 3), CRACKED, 2);
        world.setBlockState(new BlockPos(x + 1, y + 1, z + 4), RUNE_PLAIN, 2);
        world.setBlockState(new BlockPos(x + 1, y + 1, z + 5), MOSSY, 2);
        world.setBlockState(new BlockPos(x + 1, y + 1, z + 6), RUNE_MOSSY, 2);
        world.setBlockState(new BlockPos(x + 1, y + 1, z + 7), RUNE_CRACKED, 2);
        world.setBlockState(new BlockPos(x + 1, y + 1, z + 8), CRACKED, 2);
        world.setBlockState(new BlockPos(x + 1, y + 1, z + 9), RUNE_PLAIN, 2);
        world.setBlockState(new BlockPos(x + 1, y + 1, z + 10), CRACKED, 2);
        world.setBlockState(new BlockPos(x + 1, y + 1, z + 11), MOSSY, 2);
        world.setBlockState(new BlockPos(x + 1, y + 1, z + 12), RUNE_PLAIN, 2);
        world.setBlockState(new BlockPos(x + 1, y + 1, z + 13), MOSSY, 2);
        world.setBlockState(new BlockPos(x + 1, y + 1, z + 14), RUNE_CRACKED, 2);
        world.setBlockState(new BlockPos(x + 1, y + 2, z + 1), RUNE_PLAIN, 2);
        world.setBlockState(new BlockPos(x + 1, y + 2, z + 2), MOSSY, 2);
        world.setBlockState(new BlockPos(x + 1, y + 2, z + 3), RUNE_MOSSY, 2);
        world.setBlockState(new BlockPos(x + 1, y + 2, z + 4), MOSSY, 2);
        world.setBlockState(new BlockPos(x + 1, y + 2, z + 5), PLAIN, 2);
        world.setBlockState(new BlockPos(x + 1, y + 2, z + 10), PLAIN, 2);
        world.setBlockState(new BlockPos(x + 1, y + 2, z + 11), PLAIN, 2);
        world.setBlockState(new BlockPos(x + 1, y + 2, z + 12), MOSSY, 2);
        world.setBlockState(new BlockPos(x + 1, y + 2, z + 13), PLAIN, 2);
        world.setBlockState(new BlockPos(x + 1, y + 2, z + 14), MOSSY, 2);
        world.setBlockState(new BlockPos(x + 1, y + 3, z + 1), RUNE_MOSSY, 2);
        world.setBlockState(new BlockPos(x + 1, y + 3, z + 2), RUNE_PLAIN, 2);
        world.setBlockState(new BlockPos(x + 1, y + 3, z + 3), RUNE_PLAIN, 2);
        world.setBlockState(new BlockPos(x + 1, y + 3, z + 4), MOSSY, 2);
        world.setBlockState(new BlockPos(x + 1, y + 3, z + 5), CRACKED, 2);
        world.setBlockState(new BlockPos(x + 1, y + 3, z + 10), CRACKED, 2);
        world.setBlockState(new BlockPos(x + 1, y + 3, z + 11), CRACKED, 2);
        world.setBlockState(new BlockPos(x + 1, y + 3, z + 12), RUNE_MOSSY, 2);
        world.setBlockState(new BlockPos(x + 1, y + 3, z + 13), RUNE_PLAIN, 2);
        world.setBlockState(new BlockPos(x + 1, y + 3, z + 14), RUNE_MOSSY, 2);
        world.setBlockState(new BlockPos(x + 1, y + 4, z + 1), RUNE_PLAIN, 2);
        world.setBlockState(new BlockPos(x + 1, y + 4, z + 2), MOSSY, 2);
        world.setBlockState(new BlockPos(x + 1, y + 4, z + 3), RUNE_MOSSY, 2);
        world.setBlockState(new BlockPos(x + 1, y + 4, z + 4), CRACKED, 2);
        world.setBlockState(new BlockPos(x + 1, y + 4, z + 5), PLAIN, 2);
        world.setBlockState(new BlockPos(x + 1, y + 4, z + 10), RUNE_PLAIN, 2);
        world.setBlockState(new BlockPos(x + 1, y + 4, z + 11), CRACKED, 2);
        world.setBlockState(new BlockPos(x + 1, y + 4, z + 12), RUNE_CRACKED, 2);
        world.setBlockState(new BlockPos(x + 1, y + 4, z + 13), CRACKED, 2);
        world.setBlockState(new BlockPos(x + 1, y + 4, z + 14), RUNE_CRACKED, 2);
        world.setBlockState(new BlockPos(x + 1, y + 5, z + 1), CRACKED, 2);
        world.setBlockState(new BlockPos(x + 1, y + 5, z + 2), PLAIN, 2);
        world.setBlockState(new BlockPos(x + 1, y + 5, z + 3), PLAIN, 2);
        world.setBlockState(new BlockPos(x + 1, y + 5, z + 4), CRACKED, 2);
        world.setBlockState(new BlockPos(x + 1, y + 5, z + 5), CRACKED, 2);
        world.setBlockState(new BlockPos(x + 1, y + 5, z + 6), PLAIN, 2);
        world.setBlockState(new BlockPos(x + 1, y + 5, z + 7), PLAIN, 2);
        world.setBlockState(new BlockPos(x + 1, y + 5, z + 8), RUNE_PLAIN, 2);
        world.setBlockState(new BlockPos(x + 1, y + 5, z + 9), MOSSY, 2);
        world.setBlockState(new BlockPos(x + 1, y + 5, z + 10), PLAIN, 2);
        world.setBlockState(new BlockPos(x + 1, y + 5, z + 11), CRACKED, 2);
        world.setBlockState(new BlockPos(x + 1, y + 5, z + 12), RUNE_MOSSY, 2);
        world.setBlockState(new BlockPos(x + 1, y + 5, z + 13), RUNE_PLAIN, 2);
        world.setBlockState(new BlockPos(x + 1, y + 5, z + 14), RUNE_MOSSY, 2);
        world.setBlockState(new BlockPos(x + 1, y + 6, z + 1), CRACKED, 2);
        world.setBlockState(new BlockPos(x + 1, y + 6, z + 2), RUNE_MOSSY, 2);
        world.setBlockState(new BlockPos(x + 1, y + 6, z + 3), MOSSY, 2);
        world.setBlockState(new BlockPos(x + 1, y + 6, z + 4), RUNE_PLAIN, 2);
        world.setBlockState(new BlockPos(x + 1, y + 6, z + 5), RUNE_CRACKED, 2);
        world.setBlockState(new BlockPos(x + 1, y + 6, z + 6), RUNE_MOSSY, 2);
        world.setBlockState(new BlockPos(x + 1, y + 6, z + 7), RUNE_PLAIN, 2);
        world.setBlockState(new BlockPos(x + 1, y + 6, z + 8), RUNE_MOSSY, 2);
        world.setBlockState(new BlockPos(x + 1, y + 6, z + 9), MOSSY, 2);
        world.setBlockState(new BlockPos(x + 1, y + 6, z + 10), CRACKED, 2);
        world.setBlockState(new BlockPos(x + 1, y + 6, z + 11), MOSSY, 2);
        world.setBlockState(new BlockPos(x + 1, y + 6, z + 12), RUNE_CRACKED, 2);
        world.setBlockState(new BlockPos(x + 1, y + 6, z + 13), MOSSY, 2);
        world.setBlockState(new BlockPos(x + 1, y + 6, z + 14), RUNE_CRACKED, 2);
        world.setBlockState(new BlockPos(x + 1, y + 7, z + 1), RUNE_CRACKED, 2);
        world.setBlockState(new BlockPos(x + 1, y + 7, z + 2), RUNE_CRACKED, 2);
        world.setBlockState(new BlockPos(x + 1, y + 7, z + 3), RUNE_MOSSY, 2);
        world.setBlockState(new BlockPos(x + 1, y + 7, z + 4), RUNE_CRACKED, 2);
        world.setBlockState(new BlockPos(x + 1, y + 7, z + 5), MOSSY, 2);
        world.setBlockState(new BlockPos(x + 1, y + 7, z + 6), RUNE_MOSSY, 2);
        world.setBlockState(new BlockPos(x + 1, y + 7, z + 7), CRACKED, 2);
        world.setBlockState(new BlockPos(x + 1, y + 7, z + 8), CRACKED, 2);
        world.setBlockState(new BlockPos(x + 1, y + 7, z + 9), CRACKED, 2);
        world.setBlockState(new BlockPos(x + 1, y + 7, z + 10), MOSSY, 2);
        world.setBlockState(new BlockPos(x + 1, y + 7, z + 11), RUNE_MOSSY, 2);
        world.setBlockState(new BlockPos(x + 1, y + 7, z + 12), PLAIN, 2);
        world.setBlockState(new BlockPos(x + 1, y + 7, z + 13), RUNE_MOSSY, 2);
        world.setBlockState(new BlockPos(x + 1, y + 7, z + 14), RUNE_MOSSY, 2);
        world.setBlockState(new BlockPos(x + 1, y + 8, z + 1), PLAIN, 2);
        world.setBlockState(new BlockPos(x + 1, y + 8, z + 2), RUNE_MOSSY, 2);
        world.setBlockState(new BlockPos(x + 1, y + 8, z + 3), RUNE_MOSSY, 2);
        world.setBlockState(new BlockPos(x + 1, y + 8, z + 4), MOSSY, 2);
        world.setBlockState(new BlockPos(x + 1, y + 8, z + 5), RUNE_CRACKED, 2);
        world.setBlockState(new BlockPos(x + 1, y + 8, z + 6), RUNE_PLAIN, 2);
        world.setBlockState(new BlockPos(x + 1, y + 8, z + 7), PLAIN, 2);
        world.setBlockState(new BlockPos(x + 1, y + 8, z + 8), RUNE_MOSSY, 2);
        world.setBlockState(new BlockPos(x + 1, y + 8, z + 9), PLAIN, 2);
        world.setBlockState(new BlockPos(x + 1, y + 8, z + 10), MOSSY, 2);
        world.setBlockState(new BlockPos(x + 1, y + 8, z + 11), RUNE_CRACKED, 2);
        world.setBlockState(new BlockPos(x + 1, y + 8, z + 12), RUNE_PLAIN, 2);
        world.setBlockState(new BlockPos(x + 1, y + 8, z + 13), CRACKED, 2);
        world.setBlockState(new BlockPos(x + 1, y + 8, z + 14), RUNE_PLAIN, 2);
        world.setBlockState(new BlockPos(x + 2, y + 1, z + 1), RUNE_CRACKED, 2);
        world.setBlockState(new BlockPos(x + 2, y + 1, z + 2), PLAIN, 2);
        world.setBlockState(new BlockPos(x + 2, y + 1, z + 3), PLAIN, 2);
        world.setBlockState(new BlockPos(x + 2, y + 1, z + 4), CRACKED, 2);
        world.setBlockState(new BlockPos(x + 2, y + 1, z + 5), MOSSY, 2);
        world.setBlockState(new BlockPos(x + 2, y + 1, z + 6), RUNE_CRACKED, 2);
        world.setBlockState(new BlockPos(x + 2, y + 1, z + 7), RUNE_MOSSY, 2);
        world.setBlockState(new BlockPos(x + 2, y + 1, z + 8), CRACKED, 2);
        world.setBlockState(new BlockPos(x + 2, y + 1, z + 9), CRACKED, 2);
        world.setBlockState(new BlockPos(x + 2, y + 1, z + 10), RUNE_CRACKED, 2);
        world.setBlockState(new BlockPos(x + 2, y + 1, z + 11), CRACKED, 2);
        world.setBlockState(new BlockPos(x + 2, y + 1, z + 12), RUNE_PLAIN, 2);
        world.setBlockState(new BlockPos(x + 2, y + 1, z + 13), PLAIN, 2);
        world.setBlockState(new BlockPos(x + 2, y + 1, z + 14), CRACKED, 2);
        world.setBlockState(new BlockPos(x + 2, y + 2, z + 1), RUNE_CRACKED, 2);
        world.setBlockState(new BlockPos(x + 2, y + 2, z + 14), RUNE_CRACKED, 2);
        world.setBlockState(new BlockPos(x + 2, y + 3, z + 1), RUNE_CRACKED, 2);
        world.setBlockState(new BlockPos(x + 2, y + 3, z + 14), PLAIN, 2);
        world.setBlockState(new BlockPos(x + 2, y + 4, z + 1), CRACKED, 2);
        world.setBlockState(new BlockPos(x + 2, y + 4, z + 14), MOSSY, 2);
        world.setBlockState(new BlockPos(x + 2, y + 5, z + 1), RUNE_PLAIN, 2);
        world.setBlockState(new BlockPos(x + 2, y + 5, z + 14), RUNE_PLAIN, 2);
        world.setBlockState(new BlockPos(x + 2, y + 6, z + 1), CRACKED, 2);
        world.setBlockState(new BlockPos(x + 2, y + 6, z + 14), RUNE_MOSSY, 2);
        world.setBlockState(new BlockPos(x + 2, y + 7, z + 1), RUNE_PLAIN, 2);
        world.setBlockState(new BlockPos(x + 2, y + 7, z + 14), MOSSY, 2);
        world.setBlockState(new BlockPos(x + 2, y + 8, z + 1), CRACKED, 2);
        world.setBlockState(new BlockPos(x + 2, y + 8, z + 2), RUNE_CRACKED, 2);
        world.setBlockState(new BlockPos(x + 2, y + 8, z + 3), PLAIN, 2);
        world.setBlockState(new BlockPos(x + 2, y + 8, z + 4), RUNE_CRACKED, 2);
        world.setBlockState(new BlockPos(x + 2, y + 8, z + 5), RUNE_PLAIN, 2);
        world.setBlockState(new BlockPos(x + 2, y + 8, z + 6), CRACKED, 2);
        world.setBlockState(new BlockPos(x + 2, y + 8, z + 7), RUNE_CRACKED, 2);
        world.setBlockState(new BlockPos(x + 2, y + 8, z + 8), MOSSY, 2);
        world.setBlockState(new BlockPos(x + 2, y + 8, z + 9), RUNE_MOSSY, 2);
        world.setBlockState(new BlockPos(x + 2, y + 8, z + 10), RUNE_MOSSY, 2);
        world.setBlockState(new BlockPos(x + 2, y + 8, z + 11), PLAIN, 2);
        world.setBlockState(new BlockPos(x + 2, y + 8, z + 12), RUNE_MOSSY, 2);
        world.setBlockState(new BlockPos(x + 2, y + 8, z + 13), MOSSY, 2);
        world.setBlockState(new BlockPos(x + 2, y + 8, z + 14), MOSSY, 2);
        world.setBlockState(new BlockPos(x + 3, y + 1, z + 1), PLAIN, 2);
        world.setBlockState(new BlockPos(x + 3, y + 1, z + 2), RUNE_CRACKED, 2);
        world.setBlockState(new BlockPos(x + 3, y + 1, z + 3), RUNE_MOSSY, 2);
        world.setBlockState(new BlockPos(x + 3, y + 1, z + 4), MOSSY, 2);
        world.setBlockState(new BlockPos(x + 3, y + 1, z + 5), MOSSY, 2);
        world.setBlockState(new BlockPos(x + 3, y + 1, z + 6), RUNE_MOSSY, 2);
        world.setBlockState(new BlockPos(x + 3, y + 1, z + 7), RUNE_CRACKED, 2);
        world.setBlockState(new BlockPos(x + 3, y + 1, z + 8), CRACKED, 2);
        world.setBlockState(new BlockPos(x + 3, y + 1, z + 9), RUNE_CRACKED, 2);
        world.setBlockState(new BlockPos(x + 3, y + 1, z + 10), RUNE_MOSSY, 2);
        world.setBlockState(new BlockPos(x + 3, y + 1, z + 11), CRACKED, 2);
        world.setBlockState(new BlockPos(x + 3, y + 1, z + 12), RUNE_CRACKED, 2);
        world.setBlockState(new BlockPos(x + 3, y + 1, z + 13), PLAIN, 2);
        world.setBlockState(new BlockPos(x + 3, y + 1, z + 14), RUNE_MOSSY, 2);
        world.setBlockState(new BlockPos(x + 3, y + 2, z + 1), RUNE_PLAIN, 2);
        world.setBlockState(new BlockPos(x + 3, y + 2, z + 14), PLAIN, 2);
        world.setBlockState(new BlockPos(x + 3, y + 3, z + 1), RUNE_CRACKED, 2);
        world.setBlockState(new BlockPos(x + 3, y + 3, z + 14), PLAIN, 2);
        world.setBlockState(new BlockPos(x + 3, y + 4, z + 1), PLAIN, 2);
        world.setBlockState(new BlockPos(x + 3, y + 4, z + 14), PLAIN, 2);
        world.setBlockState(new BlockPos(x + 3, y + 5, z + 1), RUNE_MOSSY, 2);
        world.setBlockState(new BlockPos(x + 3, y + 5, z + 14), CRACKED, 2);
        world.setBlockState(new BlockPos(x + 3, y + 6, z + 1), CRACKED, 2);
        world.setBlockState(new BlockPos(x + 3, y + 6, z + 14), CRACKED, 2);
        world.setBlockState(new BlockPos(x + 3, y + 7, z + 1), RUNE_PLAIN, 2);
        world.setBlockState(new BlockPos(x + 3, y + 7, z + 14), CRACKED, 2);
        world.setBlockState(new BlockPos(x + 3, y + 8, z + 1), PLAIN, 2);
        world.setBlockState(new BlockPos(x + 3, y + 8, z + 2), RUNE_PLAIN, 2);
        world.setBlockState(new BlockPos(x + 3, y + 8, z + 3), RUNE_CRACKED, 2);
        world.setBlockState(new BlockPos(x + 3, y + 8, z + 4), MOSSY, 2);
        world.setBlockState(new BlockPos(x + 3, y + 8, z + 5), MOSSY, 2);
        world.setBlockState(new BlockPos(x + 3, y + 8, z + 6), RUNE_MOSSY, 2);
        world.setBlockState(new BlockPos(x + 3, y + 8, z + 7), RUNE_CRACKED, 2);
        world.setBlockState(new BlockPos(x + 3, y + 8, z + 8), PLAIN, 2);
        world.setBlockState(new BlockPos(x + 3, y + 8, z + 9), RUNE_CRACKED, 2);
        world.setBlockState(new BlockPos(x + 3, y + 8, z + 10), CRACKED, 2);
        world.setBlockState(new BlockPos(x + 3, y + 8, z + 11), RUNE_CRACKED, 2);
        world.setBlockState(new BlockPos(x + 3, y + 8, z + 12), PLAIN, 2);
        world.setBlockState(new BlockPos(x + 3, y + 8, z + 13), RUNE_CRACKED, 2);
        world.setBlockState(new BlockPos(x + 3, y + 8, z + 14), PLAIN, 2);
        world.setBlockState(new BlockPos(x + 4, y + 1, z + 1), RUNE_CRACKED, 2);
        world.setBlockState(new BlockPos(x + 4, y + 1, z + 2), PLAIN, 2);
        world.setBlockState(new BlockPos(x + 4, y + 1, z + 3), RUNE_MOSSY, 2);
        world.setBlockState(new BlockPos(x + 4, y + 1, z + 4), RUNE_PLAIN, 2);
        world.setBlockState(new BlockPos(x + 4, y + 1, z + 5), RUNE_PLAIN, 2);
        world.setBlockState(new BlockPos(x + 4, y + 1, z + 6), RUNE_CRACKED, 2);
        world.setBlockState(new BlockPos(x + 4, y + 1, z + 7), CRACKED, 2);
        world.setBlockState(new BlockPos(x + 4, y + 1, z + 8), CRACKED, 2);
        world.setBlockState(new BlockPos(x + 4, y + 1, z + 9), RUNE_CRACKED, 2);
        world.setBlockState(new BlockPos(x + 4, y + 1, z + 10), MOSSY, 2);
        world.setBlockState(new BlockPos(x + 4, y + 1, z + 11), PLAIN, 2);
        world.setBlockState(new BlockPos(x + 4, y + 1, z + 12), PLAIN, 2);
        world.setBlockState(new BlockPos(x + 4, y + 1, z + 13), MOSSY, 2);
        world.setBlockState(new BlockPos(x + 4, y + 1, z + 14), MOSSY, 2);
        world.setBlockState(new BlockPos(x + 4, y + 2, z + 1), RUNE_MOSSY, 2);
        world.setBlockState(new BlockPos(x + 4, y + 2, z + 4), RUNIC_PILLAR, 2);
        world.setBlockState(new BlockPos(x + 4, y + 2, z + 11), RUNIC_PILLAR, 2);
        world.setBlockState(new BlockPos(x + 4, y + 2, z + 14), RUNE_MOSSY, 2);
        world.setBlockState(new BlockPos(x + 4, y + 3, z + 1), MOSSY, 2);
        world.setBlockState(new BlockPos(x + 4, y + 3, z + 4), RUNIC_LAMP, 2);
        world.setBlockState(new BlockPos(x + 4, y + 3, z + 11), RUNIC_LAMP, 2);
        world.setBlockState(new BlockPos(x + 4, y + 3, z + 14), RUNE_CRACKED, 2);
        world.setBlockState(new BlockPos(x + 4, y + 4, z + 1), CRACKED, 2);
        world.setBlockState(new BlockPos(x + 4, y + 4, z + 4), RUNIC_PILLAR, 2);
        world.setBlockState(new BlockPos(x + 4, y + 4, z + 11), RUNIC_PILLAR, 2);
        world.setBlockState(new BlockPos(x + 4, y + 4, z + 14), RUNE_PLAIN, 2);
        world.setBlockState(new BlockPos(x + 4, y + 5, z + 1), RUNE_MOSSY, 2);
        world.setBlockState(new BlockPos(x + 4, y + 5, z + 4), RUNIC_PILLAR, 2);
        world.setBlockState(new BlockPos(x + 4, y + 5, z + 11), RUNIC_PILLAR, 2);
        world.setBlockState(new BlockPos(x + 4, y + 5, z + 14), CRACKED, 2);
        world.setBlockState(new BlockPos(x + 4, y + 6, z + 1), CRACKED, 2);
        world.setBlockState(new BlockPos(x + 4, y + 6, z + 4), RUNIC_LAMP, 2);
        world.setBlockState(new BlockPos(x + 4, y + 6, z + 11), RUNIC_LAMP, 2);
        world.setBlockState(new BlockPos(x + 4, y + 6, z + 14), RUNE_PLAIN, 2);
        world.setBlockState(new BlockPos(x + 4, y + 7, z + 1), CRACKED, 2);
        world.setBlockState(new BlockPos(x + 4, y + 7, z + 4), RUNIC_PILLAR, 2);
        world.setBlockState(new BlockPos(x + 4, y + 7, z + 11), RUNIC_PILLAR, 2);
        world.setBlockState(new BlockPos(x + 4, y + 7, z + 14), RUNE_CRACKED, 2);
        world.setBlockState(new BlockPos(x + 4, y + 8, z + 1), MOSSY, 2);
        world.setBlockState(new BlockPos(x + 4, y + 8, z + 2), RUNE_PLAIN, 2);
        world.setBlockState(new BlockPos(x + 4, y + 8, z + 3), RUNE_MOSSY, 2);
        world.setBlockState(new BlockPos(x + 4, y + 8, z + 4), RUNIC_LAMP, 2);
        world.setBlockState(new BlockPos(x + 4, y + 8, z + 5), RUNE_MOSSY, 2);
        world.setBlockState(new BlockPos(x + 4, y + 8, z + 6), RUNE_MOSSY, 2);
        world.setBlockState(new BlockPos(x + 4, y + 8, z + 7), RUNE_MOSSY, 2);
        world.setBlockState(new BlockPos(x + 4, y + 8, z + 8), PLAIN, 2);
        world.setBlockState(new BlockPos(x + 4, y + 8, z + 9), PLAIN, 2);
        world.setBlockState(new BlockPos(x + 4, y + 8, z + 10), RUNE_MOSSY, 2);
        world.setBlockState(new BlockPos(x + 4, y + 8, z + 11), RUNIC_LAMP, 2);
        world.setBlockState(new BlockPos(x + 4, y + 8, z + 12), RUNE_MOSSY, 2);
        world.setBlockState(new BlockPos(x + 4, y + 8, z + 13), PLAIN, 2);
        world.setBlockState(new BlockPos(x + 4, y + 8, z + 14), RUNE_PLAIN, 2);
        world.setBlockState(new BlockPos(x + 5, y + 1, z + 1), CRACKED, 2);
        world.setBlockState(new BlockPos(x + 5, y + 1, z + 2), RUNE_PLAIN, 2);
        world.setBlockState(new BlockPos(x + 5, y + 1, z + 3), MOSSY, 2);
        world.setBlockState(new BlockPos(x + 5, y + 1, z + 4), CRACKED, 2);
        world.setBlockState(new BlockPos(x + 5, y + 1, z + 5), RUNE_PLAIN, 2);
        world.setBlockState(new BlockPos(x + 5, y + 1, z + 6), PLAIN, 2);
        world.setBlockState(new BlockPos(x + 5, y + 1, z + 7), MOSSY, 2);
        world.setBlockState(new BlockPos(x + 5, y + 1, z + 8), PLAIN, 2);
        world.setBlockState(new BlockPos(x + 5, y + 1, z + 9), RUNE_CRACKED, 2);
        world.setBlockState(new BlockPos(x + 5, y + 1, z + 10), MOSSY, 2);
        world.setBlockState(new BlockPos(x + 5, y + 1, z + 11), RUNE_CRACKED, 2);
        world.setBlockState(new BlockPos(x + 5, y + 1, z + 12), RUNE_CRACKED, 2);
        world.setBlockState(new BlockPos(x + 5, y + 1, z + 13), RUNE_CRACKED, 2);
        world.setBlockState(new BlockPos(x + 5, y + 1, z + 14), RUNE_MOSSY, 2);
        world.setBlockState(new BlockPos(x + 5, y + 2, z), CRACKED, 2);
        world.setBlockState(new BlockPos(x + 5, y + 2, z + 1), RUNE_PLAIN, 2);
        world.setBlockState(new BlockPos(x + 5, y + 2, z + 14), CRACKED, 2);
        world.setBlockState(new BlockPos(x + 5, y + 2, z + 15), MOSSY, 2);
        world.setBlockState(new BlockPos(x + 5, y + 3, z), RUNIC_LAMP, 2);
        world.setBlockState(new BlockPos(x + 5, y + 3, z + 1), RUNE_CRACKED, 2);
        world.setBlockState(new BlockPos(x + 5, y + 3, z + 14), RUNE_PLAIN, 2);
        world.setBlockState(new BlockPos(x + 5, y + 3, z + 15), RUNIC_LAMP, 2);
        world.setBlockState(new BlockPos(x + 5, y + 4, z), MOSSY, 2);
        world.setBlockState(new BlockPos(x + 5, y + 4, z + 1), RUNE_CRACKED, 2);
        world.setBlockState(new BlockPos(x + 5, y + 4, z + 14), RUNE_PLAIN, 2);
        world.setBlockState(new BlockPos(x + 5, y + 4, z + 15), RUNE_MOSSY, 2);
        world.setBlockState(new BlockPos(x + 5, y + 5, z + 1), CRACKED, 2);
        world.setBlockState(new BlockPos(x + 5, y + 5, z + 14), RUNE_PLAIN, 2);
        world.setBlockState(new BlockPos(x + 5, y + 6, z + 1), RUNE_CRACKED, 2);
        world.setBlockState(new BlockPos(x + 5, y + 6, z + 14), CRACKED, 2);
        world.setBlockState(new BlockPos(x + 5, y + 7, z + 1), RUNE_MOSSY, 2);
        world.setBlockState(new BlockPos(x + 5, y + 7, z + 14), RUNE_MOSSY, 2);
        world.setBlockState(new BlockPos(x + 5, y + 8, z + 1), RUNE_CRACKED, 2);
        world.setBlockState(new BlockPos(x + 5, y + 8, z + 2), RUNE_PLAIN, 2);
        world.setBlockState(new BlockPos(x + 5, y + 8, z + 3), RUNE_PLAIN, 2);
        world.setBlockState(new BlockPos(x + 5, y + 8, z + 4), CRACKED, 2);
        world.setBlockState(new BlockPos(x + 5, y + 8, z + 5), RUNE_PLAIN, 2);
        world.setBlockState(new BlockPos(x + 5, y + 8, z + 6), RUNE_CRACKED, 2);
        world.setBlockState(new BlockPos(x + 5, y + 8, z + 7), CRACKED, 2);
        world.setBlockState(new BlockPos(x + 5, y + 8, z + 8), RUNE_CRACKED, 2);
        world.setBlockState(new BlockPos(x + 5, y + 8, z + 9), PLAIN, 2);
        world.setBlockState(new BlockPos(x + 5, y + 8, z + 10), RUNE_CRACKED, 2);
        world.setBlockState(new BlockPos(x + 5, y + 8, z + 11), RUNE_PLAIN, 2);
        world.setBlockState(new BlockPos(x + 5, y + 8, z + 12), RUNE_MOSSY, 2);
        world.setBlockState(new BlockPos(x + 5, y + 8, z + 13), RUNE_PLAIN, 2);
        world.setBlockState(new BlockPos(x + 5, y + 8, z + 14), RUNE_PLAIN, 2);
        world.setBlockState(new BlockPos(x + 6, y + 1, z), CRACKED, 2);
        world.setBlockState(new BlockPos(x + 6, y + 1, z + 1), PLAIN, 2);
        world.setBlockState(new BlockPos(x + 6, y + 1, z + 2), RUNE_PLAIN, 2);
        world.setBlockState(new BlockPos(x + 6, y + 1, z + 3), RUNE_MOSSY, 2);
        world.setBlockState(new BlockPos(x + 6, y + 1, z + 4), PLAIN, 2);
        world.setBlockState(new BlockPos(x + 6, y + 1, z + 5), RUNE_MOSSY, 2);
        world.setBlockState(new BlockPos(x + 6, y + 1, z + 6), PLAIN, 2);
        world.setBlockState(new BlockPos(x + 6, y + 1, z + 7), CRACKED, 2);
        world.setBlockState(new BlockPos(x + 6, y + 1, z + 8), RUNE_CRACKED, 2);
        world.setBlockState(new BlockPos(x + 6, y + 1, z + 9), CRACKED, 2);
        world.setBlockState(new BlockPos(x + 6, y + 1, z + 10), RUNE_CRACKED, 2);
        world.setBlockState(new BlockPos(x + 6, y + 1, z + 11), PLAIN, 2);
        world.setBlockState(new BlockPos(x + 6, y + 1, z + 12), RUNE_CRACKED, 2);
        world.setBlockState(new BlockPos(x + 6, y + 1, z + 13), PLAIN, 2);
        world.setBlockState(new BlockPos(x + 6, y + 1, z + 14), PLAIN, 2);
        world.setBlockState(new BlockPos(x + 6, y + 1, z + 15), MOSSY, 2);
        world.setBlockState(new BlockPos(x + 6, y + 2, z), RUNE_CRACKED, 2);
        world.setBlockState(new BlockPos(x + 6, y + 2, z + 15), RUNE_MOSSY, 2);
        world.setBlockState(new BlockPos(x + 6, y + 3, z), PLAIN, 2);
        world.setBlockState(new BlockPos(x + 6, y + 3, z + 15), PLAIN, 2);
        world.setBlockState(new BlockPos(x + 6, y + 4, z), PLAIN, 2);
        world.setBlockState(new BlockPos(x + 6, y + 4, z + 15), RUNE_CRACKED, 2);
        world.setBlockState(new BlockPos(x + 6, y + 5, z), CRACKED, 2);
        world.setBlockState(new BlockPos(x + 6, y + 5, z + 1), CRACKED, 2);
        world.setBlockState(new BlockPos(x + 6, y + 5, z + 14), MOSSY, 2);
        world.setBlockState(new BlockPos(x + 6, y + 5, z + 15), MOSSY, 2);
        world.setBlockState(new BlockPos(x + 6, y + 6, z + 1), PLAIN, 2);
        world.setBlockState(new BlockPos(x + 6, y + 6, z + 14), RUNE_CRACKED, 2);
        world.setBlockState(new BlockPos(x + 6, y + 7, z + 1), MOSSY, 2);
        world.setBlockState(new BlockPos(x + 6, y + 7, z + 14), RUNE_CRACKED, 2);
        world.setBlockState(new BlockPos(x + 6, y + 8, z + 1), MOSSY, 2);
        world.setBlockState(new BlockPos(x + 6, y + 8, z + 2), RUNE_CRACKED, 2);
        world.setBlockState(new BlockPos(x + 6, y + 8, z + 3), RUNE_MOSSY, 2);
        world.setBlockState(new BlockPos(x + 6, y + 8, z + 4), RUNE_MOSSY, 2);
        world.setBlockState(new BlockPos(x + 6, y + 8, z + 5), RUNE_PLAIN, 2);
        world.setBlockState(new BlockPos(x + 6, y + 8, z + 6), MOSSY, 2);
        world.setBlockState(new BlockPos(x + 6, y + 8, z + 7), RUNE_PLAIN, 2);
        world.setBlockState(new BlockPos(x + 6, y + 8, z + 8), RUNE_MOSSY, 2);
        world.setBlockState(new BlockPos(x + 6, y + 8, z + 9), MOSSY, 2);
        world.setBlockState(new BlockPos(x + 6, y + 8, z + 10), RUNE_CRACKED, 2);
        world.setBlockState(new BlockPos(x + 6, y + 8, z + 11), CRACKED, 2);
        world.setBlockState(new BlockPos(x + 6, y + 8, z + 12), RUNE_PLAIN, 2);
        world.setBlockState(new BlockPos(x + 6, y + 8, z + 13), CRACKED, 2);
        world.setBlockState(new BlockPos(x + 6, y + 8, z + 14), CRACKED, 2);
        world.setBlockState(new BlockPos(x + 7, y + 1, z), RUNE_MOSSY, 2);
        world.setBlockState(new BlockPos(x + 7, y + 1, z + 1), RUNE_MOSSY, 2);
        world.setBlockState(new BlockPos(x + 7, y + 1, z + 2), RUNE_CRACKED, 2);
        world.setBlockState(new BlockPos(x + 7, y + 1, z + 3), MOSSY, 2);
        world.setBlockState(new BlockPos(x + 7, y + 1, z + 4), CRACKED, 2);
        world.setBlockState(new BlockPos(x + 7, y + 1, z + 5), RUNE_CRACKED, 2);
        world.setBlockState(new BlockPos(x + 7, y + 1, z + 6), RUNE_CRACKED, 2);
        world.setBlockState(new BlockPos(x + 7, y + 1, z + 7), RUNE_CRACKED, 2);
        world.setBlockState(new BlockPos(x + 7, y + 1, z + 8), RUNE_CRACKED, 2);
        world.setBlockState(new BlockPos(x + 7, y + 1, z + 9), CRACKED, 2);
        world.setBlockState(new BlockPos(x + 7, y + 1, z + 10), MOSSY, 2);
        world.setBlockState(new BlockPos(x + 7, y + 1, z + 11), MOSSY, 2);
        world.setBlockState(new BlockPos(x + 7, y + 1, z + 12), RUNE_CRACKED, 2);
        world.setBlockState(new BlockPos(x + 7, y + 1, z + 13), MOSSY, 2);
        world.setBlockState(new BlockPos(x + 7, y + 1, z + 14), MOSSY, 2);
        world.setBlockState(new BlockPos(x + 7, y + 1, z + 15), RUNE_CRACKED, 2);
        world.setBlockState(new BlockPos(x + 7, y + 2, z), PLAIN, 2);
        world.setBlockState(new BlockPos(x + 7, y + 2, z + 15), RUNE_MOSSY, 2);
        world.setBlockState(new BlockPos(x + 7, y + 3, z), KEY_STONE, 2);
        world.setBlockState(new BlockPos(x + 7, y + 3, z + 15), KEY_STONE, 2);
        world.setBlockState(new BlockPos(x + 7, y + 4, z), RUNE_MOSSY, 2);
        world.setBlockState(new BlockPos(x + 7, y + 4, z + 15), MOSSY, 2);
        world.setBlockState(new BlockPos(x + 7, y + 5, z), PLAIN, 2);
        world.setBlockState(new BlockPos(x + 7, y + 5, z + 1), RUNE_PLAIN, 2);
        world.setBlockState(new BlockPos(x + 7, y + 5, z + 14), CRACKED, 2);
        world.setBlockState(new BlockPos(x + 7, y + 5, z + 15), RUNE_MOSSY, 2);
        world.setBlockState(new BlockPos(x + 7, y + 6, z + 1), RUNE_PLAIN, 2);
        world.setBlockState(new BlockPos(x + 7, y + 6, z + 14), RUNE_PLAIN, 2);
        world.setBlockState(new BlockPos(x + 7, y + 7, z + 1), RUNE_PLAIN, 2);
        world.setBlockState(new BlockPos(x + 7, y + 7, z + 14), CRACKED, 2);
        world.setBlockState(new BlockPos(x + 7, y + 8, z + 1), RUNE_MOSSY, 2);
        world.setBlockState(new BlockPos(x + 7, y + 8, z + 2), RUNE_CRACKED, 2);
        world.setBlockState(new BlockPos(x + 7, y + 8, z + 3), RUNE_PLAIN, 2);
        world.setBlockState(new BlockPos(x + 7, y + 8, z + 4), MOSSY, 2);
        world.setBlockState(new BlockPos(x + 7, y + 8, z + 5), PLAIN, 2);
        world.setBlockState(new BlockPos(x + 7, y + 8, z + 6), RUNE_MOSSY, 2);
        world.setBlockState(new BlockPos(x + 7, y + 8, z + 7), RUNE_CRACKED, 2);
        world.setBlockState(new BlockPos(x + 7, y + 8, z + 8), RUNE_CRACKED, 2);
        world.setBlockState(new BlockPos(x + 7, y + 8, z + 9), PLAIN, 2);
        world.setBlockState(new BlockPos(x + 7, y + 8, z + 10), RUNE_PLAIN, 2);
        world.setBlockState(new BlockPos(x + 7, y + 8, z + 11), RUNE_MOSSY, 2);
        world.setBlockState(new BlockPos(x + 7, y + 8, z + 12), RUNE_MOSSY, 2);
        world.setBlockState(new BlockPos(x + 7, y + 8, z + 13), RUNE_CRACKED, 2);
        world.setBlockState(new BlockPos(x + 7, y + 8, z + 14), RUNE_PLAIN, 2);
        world.setBlockState(new BlockPos(x + 8, y + 1, z), PLAIN, 2);
        world.setBlockState(new BlockPos(x + 8, y + 1, z + 1), PLAIN, 2);
        world.setBlockState(new BlockPos(x + 8, y + 1, z + 2), RUNE_PLAIN, 2);
        world.setBlockState(new BlockPos(x + 8, y + 1, z + 3), MOSSY, 2);
        world.setBlockState(new BlockPos(x + 8, y + 1, z + 4), RUNE_CRACKED, 2);
        world.setBlockState(new BlockPos(x + 8, y + 1, z + 5), RUNE_PLAIN, 2);
        world.setBlockState(new BlockPos(x + 8, y + 1, z + 6), CRACKED, 2);
        world.setBlockState(new BlockPos(x + 8, y + 1, z + 7), RUNE_CRACKED, 2);
        world.setBlockState(new BlockPos(x + 8, y + 1, z + 8), RUNE_MOSSY, 2);
        world.setBlockState(new BlockPos(x + 8, y + 1, z + 9), MOSSY, 2);
        world.setBlockState(new BlockPos(x + 8, y + 1, z + 10), RUNE_MOSSY, 2);
        world.setBlockState(new BlockPos(x + 8, y + 1, z + 11), RUNE_MOSSY, 2);
        world.setBlockState(new BlockPos(x + 8, y + 1, z + 12), PLAIN, 2);
        world.setBlockState(new BlockPos(x + 8, y + 1, z + 13), PLAIN, 2);
        world.setBlockState(new BlockPos(x + 8, y + 1, z + 14), RUNE_PLAIN, 2);
        world.setBlockState(new BlockPos(x + 8, y + 1, z + 15), RUNE_CRACKED, 2);
        world.setBlockState(new BlockPos(x + 8, y + 2, z), MOSSY, 2);
        world.setBlockState(new BlockPos(x + 8, y + 2, z + 15), RUNE_CRACKED, 2);
        world.setBlockState(new BlockPos(x + 8, y + 3, z), KEY_STONE, 2);
        world.setBlockState(new BlockPos(x + 8, y + 3, z + 15), KEY_STONE, 2);
        world.setBlockState(new BlockPos(x + 8, y + 4, z), RUNE_MOSSY, 2);
        world.setBlockState(new BlockPos(x + 8, y + 4, z + 15), RUNE_PLAIN, 2);
        world.setBlockState(new BlockPos(x + 8, y + 5, z), PLAIN, 2);
        world.setBlockState(new BlockPos(x + 8, y + 5, z + 1), RUNE_CRACKED, 2);
        world.setBlockState(new BlockPos(x + 8, y + 5, z + 14), RUNE_MOSSY, 2);
        world.setBlockState(new BlockPos(x + 8, y + 5, z + 15), RUNE_PLAIN, 2);
        world.setBlockState(new BlockPos(x + 8, y + 6, z + 1), RUNE_MOSSY, 2);
        world.setBlockState(new BlockPos(x + 8, y + 6, z + 14), RUNE_CRACKED, 2);
        world.setBlockState(new BlockPos(x + 8, y + 7, z + 1), RUNE_CRACKED, 2);
        world.setBlockState(new BlockPos(x + 8, y + 7, z + 14), MOSSY, 2);
        world.setBlockState(new BlockPos(x + 8, y + 8, z + 1), RUNE_PLAIN, 2);
        world.setBlockState(new BlockPos(x + 8, y + 8, z + 2), CRACKED, 2);
        world.setBlockState(new BlockPos(x + 8, y + 8, z + 3), RUNE_MOSSY, 2);
        world.setBlockState(new BlockPos(x + 8, y + 8, z + 4), MOSSY, 2);
        world.setBlockState(new BlockPos(x + 8, y + 8, z + 5), RUNE_MOSSY, 2);
        world.setBlockState(new BlockPos(x + 8, y + 8, z + 6), CRACKED, 2);
        world.setBlockState(new BlockPos(x + 8, y + 8, z + 7), CRACKED, 2);
        world.setBlockState(new BlockPos(x + 8, y + 8, z + 8), RUNE_PLAIN, 2);
        world.setBlockState(new BlockPos(x + 8, y + 8, z + 9), PLAIN, 2);
        world.setBlockState(new BlockPos(x + 8, y + 8, z + 10), CRACKED, 2);
        world.setBlockState(new BlockPos(x + 8, y + 8, z + 11), MOSSY, 2);
        world.setBlockState(new BlockPos(x + 8, y + 8, z + 12), MOSSY, 2);
        world.setBlockState(new BlockPos(x + 8, y + 8, z + 13), MOSSY, 2);
        world.setBlockState(new BlockPos(x + 8, y + 8, z + 14), RUNE_PLAIN, 2);
        world.setBlockState(new BlockPos(x + 9, y + 1, z), RUNE_CRACKED, 2);
        world.setBlockState(new BlockPos(x + 9, y + 1, z + 1), CRACKED, 2);
        world.setBlockState(new BlockPos(x + 9, y + 1, z + 2), RUNE_MOSSY, 2);
        world.setBlockState(new BlockPos(x + 9, y + 1, z + 3), RUNE_CRACKED, 2);
        world.setBlockState(new BlockPos(x + 9, y + 1, z + 4), PLAIN, 2);
        world.setBlockState(new BlockPos(x + 9, y + 1, z + 5), PLAIN, 2);
        world.setBlockState(new BlockPos(x + 9, y + 1, z + 6), RUNE_CRACKED, 2);
        world.setBlockState(new BlockPos(x + 9, y + 1, z + 7), CRACKED, 2);
        world.setBlockState(new BlockPos(x + 9, y + 1, z + 8), CRACKED, 2);
        world.setBlockState(new BlockPos(x + 9, y + 1, z + 9), RUNE_CRACKED, 2);
        world.setBlockState(new BlockPos(x + 9, y + 1, z + 10), CRACKED, 2);
        world.setBlockState(new BlockPos(x + 9, y + 1, z + 11), CRACKED, 2);
        world.setBlockState(new BlockPos(x + 9, y + 1, z + 12), CRACKED, 2);
        world.setBlockState(new BlockPos(x + 9, y + 1, z + 13), RUNE_PLAIN, 2);
        world.setBlockState(new BlockPos(x + 9, y + 1, z + 14), RUNE_CRACKED, 2);
        world.setBlockState(new BlockPos(x + 9, y + 1, z + 15), MOSSY, 2);
        world.setBlockState(new BlockPos(x + 9, y + 2, z), PLAIN, 2);
        world.setBlockState(new BlockPos(x + 9, y + 2, z + 15), RUNE_CRACKED, 2);
        world.setBlockState(new BlockPos(x + 9, y + 3, z), CRACKED, 2);
        world.setBlockState(new BlockPos(x + 9, y + 3, z + 15), RUNE_PLAIN, 2);
        world.setBlockState(new BlockPos(x + 9, y + 4, z), RUNE_PLAIN, 2);
        world.setBlockState(new BlockPos(x + 9, y + 4, z + 15), PLAIN, 2);
        world.setBlockState(new BlockPos(x + 9, y + 5, z), MOSSY, 2);
        world.setBlockState(new BlockPos(x + 9, y + 5, z + 1), RUNE_MOSSY, 2);
        world.setBlockState(new BlockPos(x + 9, y + 5, z + 14), MOSSY, 2);
        world.setBlockState(new BlockPos(x + 9, y + 5, z + 15), RUNE_MOSSY, 2);
        world.setBlockState(new BlockPos(x + 9, y + 6, z + 1), PLAIN, 2);
        world.setBlockState(new BlockPos(x + 9, y + 6, z + 14), PLAIN, 2);
        world.setBlockState(new BlockPos(x + 9, y + 7, z + 1), MOSSY, 2);
        world.setBlockState(new BlockPos(x + 9, y + 7, z + 14), MOSSY, 2);
        world.setBlockState(new BlockPos(x + 9, y + 8, z + 1), PLAIN, 2);
        world.setBlockState(new BlockPos(x + 9, y + 8, z + 2), MOSSY, 2);
        world.setBlockState(new BlockPos(x + 9, y + 8, z + 3), RUNE_MOSSY, 2);
        world.setBlockState(new BlockPos(x + 9, y + 8, z + 4), RUNE_PLAIN, 2);
        world.setBlockState(new BlockPos(x + 9, y + 8, z + 5), CRACKED, 2);
        world.setBlockState(new BlockPos(x + 9, y + 8, z + 6), RUNE_CRACKED, 2);
        world.setBlockState(new BlockPos(x + 9, y + 8, z + 7), CRACKED, 2);
        world.setBlockState(new BlockPos(x + 9, y + 8, z + 8), RUNE_MOSSY, 2);
        world.setBlockState(new BlockPos(x + 9, y + 8, z + 9), MOSSY, 2);
        world.setBlockState(new BlockPos(x + 9, y + 8, z + 10), PLAIN, 2);
        world.setBlockState(new BlockPos(x + 9, y + 8, z + 11), PLAIN, 2);
        world.setBlockState(new BlockPos(x + 9, y + 8, z + 12), MOSSY, 2);
        world.setBlockState(new BlockPos(x + 9, y + 8, z + 13), RUNE_CRACKED, 2);
        world.setBlockState(new BlockPos(x + 9, y + 8, z + 14), CRACKED, 2);
        world.setBlockState(new BlockPos(x + 10, y + 1, z + 1), RUNE_CRACKED, 2);
        world.setBlockState(new BlockPos(x + 10, y + 1, z + 2), RUNE_PLAIN, 2);
        world.setBlockState(new BlockPos(x + 10, y + 1, z + 3), PLAIN, 2);
        world.setBlockState(new BlockPos(x + 10, y + 1, z + 4), PLAIN, 2);
        world.setBlockState(new BlockPos(x + 10, y + 1, z + 5), RUNE_CRACKED, 2);
        world.setBlockState(new BlockPos(x + 10, y + 1, z + 6), PLAIN, 2);
        world.setBlockState(new BlockPos(x + 10, y + 1, z + 7), RUNE_PLAIN, 2);
        world.setBlockState(new BlockPos(x + 10, y + 1, z + 8), MOSSY, 2);
        world.setBlockState(new BlockPos(x + 10, y + 1, z + 9), MOSSY, 2);
        world.setBlockState(new BlockPos(x + 10, y + 1, z + 10), RUNE_CRACKED, 2);
        world.setBlockState(new BlockPos(x + 10, y + 1, z + 11), CRACKED, 2);
        world.setBlockState(new BlockPos(x + 10, y + 1, z + 12), CRACKED, 2);
        world.setBlockState(new BlockPos(x + 10, y + 1, z + 13), MOSSY, 2);
        world.setBlockState(new BlockPos(x + 10, y + 1, z + 14), CRACKED, 2);
        world.setBlockState(new BlockPos(x + 10, y + 2, z), CRACKED, 2);
        world.setBlockState(new BlockPos(x + 10, y + 2, z + 1), RUNE_MOSSY, 2);
        world.setBlockState(new BlockPos(x + 10, y + 2, z + 14), PLAIN, 2);
        world.setBlockState(new BlockPos(x + 10, y + 2, z + 15), MOSSY, 2);
        world.setBlockState(new BlockPos(x + 10, y + 3, z), RUNIC_LAMP, 2);
        world.setBlockState(new BlockPos(x + 10, y + 3, z + 1), CRACKED, 2);
        world.setBlockState(new BlockPos(x + 10, y + 3, z + 14), RUNE_PLAIN, 2);
        world.setBlockState(new BlockPos(x + 10, y + 3, z + 15), RUNIC_LAMP, 2);
        world.setBlockState(new BlockPos(x + 10, y + 4, z), CRACKED, 2);
        world.setBlockState(new BlockPos(x + 10, y + 4, z + 1), RUNE_CRACKED, 2);
        world.setBlockState(new BlockPos(x + 10, y + 4, z + 14), PLAIN, 2);
        world.setBlockState(new BlockPos(x + 10, y + 4, z + 15), CRACKED, 2);
        world.setBlockState(new BlockPos(x + 10, y + 5, z + 1), MOSSY, 2);
        world.setBlockState(new BlockPos(x + 10, y + 5, z + 14), RUNE_CRACKED, 2);
        world.setBlockState(new BlockPos(x + 10, y + 6, z + 1), CRACKED, 2);
        world.setBlockState(new BlockPos(x + 10, y + 6, z + 14), RUNE_PLAIN, 2);
        world.setBlockState(new BlockPos(x + 10, y + 7, z + 1), RUNE_MOSSY, 2);
        world.setBlockState(new BlockPos(x + 10, y + 7, z + 14), RUNE_MOSSY, 2);
        world.setBlockState(new BlockPos(x + 10, y + 8, z + 1), PLAIN, 2);
        world.setBlockState(new BlockPos(x + 10, y + 8, z + 2), PLAIN, 2);
        world.setBlockState(new BlockPos(x + 10, y + 8, z + 3), RUNE_PLAIN, 2);
        world.setBlockState(new BlockPos(x + 10, y + 8, z + 4), MOSSY, 2);
        world.setBlockState(new BlockPos(x + 10, y + 8, z + 5), RUNE_MOSSY, 2);
        world.setBlockState(new BlockPos(x + 10, y + 8, z + 6), RUNE_CRACKED, 2);
        world.setBlockState(new BlockPos(x + 10, y + 8, z + 7), MOSSY, 2);
        world.setBlockState(new BlockPos(x + 10, y + 8, z + 8), RUNE_CRACKED, 2);
        world.setBlockState(new BlockPos(x + 10, y + 8, z + 9), PLAIN, 2);
        world.setBlockState(new BlockPos(x + 10, y + 8, z + 10), RUNE_MOSSY, 2);
        world.setBlockState(new BlockPos(x + 10, y + 8, z + 11), RUNE_MOSSY, 2);
        world.setBlockState(new BlockPos(x + 10, y + 8, z + 12), CRACKED, 2);
        world.setBlockState(new BlockPos(x + 10, y + 8, z + 13), RUNE_MOSSY, 2);
        world.setBlockState(new BlockPos(x + 10, y + 8, z + 14), CRACKED, 2);
        world.setBlockState(new BlockPos(x + 11, y + 1, z + 1), RUNE_CRACKED, 2);
        world.setBlockState(new BlockPos(x + 11, y + 1, z + 2), PLAIN, 2);
        world.setBlockState(new BlockPos(x + 11, y + 1, z + 3), RUNE_PLAIN, 2);
        world.setBlockState(new BlockPos(x + 11, y + 1, z + 4), CRACKED, 2);
        world.setBlockState(new BlockPos(x + 11, y + 1, z + 5), RUNE_PLAIN, 2);
        world.setBlockState(new BlockPos(x + 11, y + 1, z + 6), RUNE_PLAIN, 2);
        world.setBlockState(new BlockPos(x + 11, y + 1, z + 7), PLAIN, 2);
        world.setBlockState(new BlockPos(x + 11, y + 1, z + 8), RUNE_MOSSY, 2);
        world.setBlockState(new BlockPos(x + 11, y + 1, z + 9), PLAIN, 2);
        world.setBlockState(new BlockPos(x + 11, y + 1, z + 10), RUNE_PLAIN, 2);
        world.setBlockState(new BlockPos(x + 11, y + 1, z + 11), RUNE_CRACKED, 2);
        world.setBlockState(new BlockPos(x + 11, y + 1, z + 12), PLAIN, 2);
        world.setBlockState(new BlockPos(x + 11, y + 1, z + 13), PLAIN, 2);
        world.setBlockState(new BlockPos(x + 11, y + 1, z + 14), CRACKED, 2);
        world.setBlockState(new BlockPos(x + 11, y + 2, z), PLAIN, 2);
        world.setBlockState(new BlockPos(x + 11, y + 2, z + 1), RUNE_CRACKED, 2);
        world.setBlockState(new BlockPos(x + 11, y + 2, z + 4), RUNIC_PILLAR, 2);
        world.setBlockState(new BlockPos(x + 11, y + 2, z + 11), RUNIC_PILLAR, 2);
        world.setBlockState(new BlockPos(x + 11, y + 2, z + 14), MOSSY, 2);
        world.setBlockState(new BlockPos(x + 11, y + 3, z + 1), PLAIN, 2);
        world.setBlockState(new BlockPos(x + 11, y + 3, z + 4), RUNIC_LAMP, 2);
        world.setBlockState(new BlockPos(x + 11, y + 3, z + 11), RUNIC_LAMP, 2);
        world.setBlockState(new BlockPos(x + 11, y + 3, z + 14), PLAIN, 2);
        world.setBlockState(new BlockPos(x + 11, y + 4, z + 1), CRACKED, 2);
        world.setBlockState(new BlockPos(x + 11, y + 4, z + 4), RUNIC_PILLAR, 2);
        world.setBlockState(new BlockPos(x + 11, y + 4, z + 11), RUNIC_PILLAR, 2);
        world.setBlockState(new BlockPos(x + 11, y + 4, z + 14), RUNE_PLAIN, 2);
        world.setBlockState(new BlockPos(x + 11, y + 5, z + 1), PLAIN, 2);
        world.setBlockState(new BlockPos(x + 11, y + 5, z + 4), RUNIC_PILLAR, 2);
        world.setBlockState(new BlockPos(x + 11, y + 5, z + 11), RUNIC_PILLAR, 2);
        world.setBlockState(new BlockPos(x + 11, y + 5, z + 14), MOSSY, 2);
        world.setBlockState(new BlockPos(x + 11, y + 6, z + 1), RUNE_CRACKED, 2);
        world.setBlockState(new BlockPos(x + 11, y + 6, z + 4), RUNIC_LAMP, 2);
        world.setBlockState(new BlockPos(x + 11, y + 6, z + 11), RUNIC_LAMP, 2);
        world.setBlockState(new BlockPos(x + 11, y + 6, z + 14), RUNE_CRACKED, 2);
        world.setBlockState(new BlockPos(x + 11, y + 7, z + 1), PLAIN, 2);
        world.setBlockState(new BlockPos(x + 11, y + 7, z + 4), RUNIC_PILLAR, 2);
        world.setBlockState(new BlockPos(x + 11, y + 7, z + 11), RUNIC_PILLAR, 2);
        world.setBlockState(new BlockPos(x + 11, y + 7, z + 14), RUNE_PLAIN, 2);
        world.setBlockState(new BlockPos(x + 11, y + 8, z + 1), MOSSY, 2);
        world.setBlockState(new BlockPos(x + 11, y + 8, z + 2), RUNE_PLAIN, 2);
        world.setBlockState(new BlockPos(x + 11, y + 8, z + 3), PLAIN, 2);
        world.setBlockState(new BlockPos(x + 11, y + 8, z + 4), RUNIC_LAMP, 2);
        world.setBlockState(new BlockPos(x + 11, y + 8, z + 5), RUNE_MOSSY, 2);
        world.setBlockState(new BlockPos(x + 11, y + 8, z + 6), CRACKED, 2);
        world.setBlockState(new BlockPos(x + 11, y + 8, z + 7), MOSSY, 2);
        world.setBlockState(new BlockPos(x + 11, y + 8, z + 8), RUNE_CRACKED, 2);
        world.setBlockState(new BlockPos(x + 11, y + 8, z + 9), PLAIN, 2);
        world.setBlockState(new BlockPos(x + 11, y + 8, z + 10), CRACKED, 2);
        world.setBlockState(new BlockPos(x + 11, y + 8, z + 11), RUNIC_LAMP, 2);
        world.setBlockState(new BlockPos(x + 11, y + 8, z + 12), RUNE_MOSSY, 2);
        world.setBlockState(new BlockPos(x + 11, y + 8, z + 13), RUNE_CRACKED, 2);
        world.setBlockState(new BlockPos(x + 11, y + 8, z + 14), CRACKED, 2);
        world.setBlockState(new BlockPos(x + 12, y + 1, z + 1), RUNE_CRACKED, 2);
        world.setBlockState(new BlockPos(x + 12, y + 1, z + 2), RUNE_MOSSY, 2);
        world.setBlockState(new BlockPos(x + 12, y + 1, z + 3), RUNE_CRACKED, 2);
        world.setBlockState(new BlockPos(x + 12, y + 1, z + 4), CRACKED, 2);
        world.setBlockState(new BlockPos(x + 12, y + 1, z + 5), PLAIN, 2);
        world.setBlockState(new BlockPos(x + 12, y + 1, z + 6), CRACKED, 2);
        world.setBlockState(new BlockPos(x + 12, y + 1, z + 7), MOSSY, 2);
        world.setBlockState(new BlockPos(x + 12, y + 1, z + 8), RUNE_CRACKED, 2);
        world.setBlockState(new BlockPos(x + 12, y + 1, z + 9), CRACKED, 2);
        world.setBlockState(new BlockPos(x + 12, y + 1, z + 10), RUNE_PLAIN, 2);
        world.setBlockState(new BlockPos(x + 12, y + 1, z + 11), RUNE_CRACKED, 2);
        world.setBlockState(new BlockPos(x + 12, y + 1, z + 12), RUNE_CRACKED, 2);
        world.setBlockState(new BlockPos(x + 12, y + 1, z + 13), MOSSY, 2);
        world.setBlockState(new BlockPos(x + 12, y + 1, z + 14), PLAIN, 2);
        world.setBlockState(new BlockPos(x + 12, y + 2, z + 1), CRACKED, 2);
        world.setBlockState(new BlockPos(x + 12, y + 2, z + 14), RUNE_CRACKED, 2);
        world.setBlockState(new BlockPos(x + 12, y + 3, z + 1), RUNE_PLAIN, 2);
        world.setBlockState(new BlockPos(x + 12, y + 3, z + 14), RUNE_MOSSY, 2);
        world.setBlockState(new BlockPos(x + 12, y + 4, z + 1), PLAIN, 2);
        world.setBlockState(new BlockPos(x + 12, y + 4, z + 14), RUNE_CRACKED, 2);
        world.setBlockState(new BlockPos(x + 12, y + 5, z + 1), CRACKED, 2);
        world.setBlockState(new BlockPos(x + 12, y + 5, z + 14), PLAIN, 2);
        world.setBlockState(new BlockPos(x + 12, y + 6, z + 1), RUNE_MOSSY, 2);
        world.setBlockState(new BlockPos(x + 12, y + 6, z + 14), MOSSY, 2);
        world.setBlockState(new BlockPos(x + 12, y + 7, z + 1), RUNE_PLAIN, 2);
        world.setBlockState(new BlockPos(x + 12, y + 7, z + 14), RUNE_MOSSY, 2);
        world.setBlockState(new BlockPos(x + 12, y + 8, z + 1), MOSSY, 2);
        world.setBlockState(new BlockPos(x + 12, y + 8, z + 2), CRACKED, 2);
        world.setBlockState(new BlockPos(x + 12, y + 8, z + 3), RUNE_CRACKED, 2);
        world.setBlockState(new BlockPos(x + 12, y + 8, z + 4), PLAIN, 2);
        world.setBlockState(new BlockPos(x + 12, y + 8, z + 5), PLAIN, 2);
        world.setBlockState(new BlockPos(x + 12, y + 8, z + 6), MOSSY, 2);
        world.setBlockState(new BlockPos(x + 12, y + 8, z + 7), CRACKED, 2);
        world.setBlockState(new BlockPos(x + 12, y + 8, z + 8), MOSSY, 2);
        world.setBlockState(new BlockPos(x + 12, y + 8, z + 9), MOSSY, 2);
        world.setBlockState(new BlockPos(x + 12, y + 8, z + 10), RUNE_PLAIN, 2);
        world.setBlockState(new BlockPos(x + 12, y + 8, z + 11), CRACKED, 2);
        world.setBlockState(new BlockPos(x + 12, y + 8, z + 12), RUNE_PLAIN, 2);
        world.setBlockState(new BlockPos(x + 12, y + 8, z + 13), RUNE_CRACKED, 2);
        world.setBlockState(new BlockPos(x + 12, y + 8, z + 14), RUNE_PLAIN, 2);
        world.setBlockState(new BlockPos(x + 13, y + 1, z + 1), MOSSY, 2);
        world.setBlockState(new BlockPos(x + 13, y + 1, z + 2), CRACKED, 2);
        world.setBlockState(new BlockPos(x + 13, y + 1, z + 3), MOSSY, 2);
        world.setBlockState(new BlockPos(x + 13, y + 1, z + 4), RUNE_CRACKED, 2);
        world.setBlockState(new BlockPos(x + 13, y + 1, z + 5), RUNE_CRACKED, 2);
        world.setBlockState(new BlockPos(x + 13, y + 1, z + 6), CRACKED, 2);
        world.setBlockState(new BlockPos(x + 13, y + 1, z + 7), RUNE_MOSSY, 2);
        world.setBlockState(new BlockPos(x + 13, y + 1, z + 8), PLAIN, 2);
        world.setBlockState(new BlockPos(x + 13, y + 1, z + 9), RUNE_PLAIN, 2);
        world.setBlockState(new BlockPos(x + 13, y + 1, z + 10), RUNE_CRACKED, 2);
        world.setBlockState(new BlockPos(x + 13, y + 1, z + 11), RUNE_MOSSY, 2);
        world.setBlockState(new BlockPos(x + 13, y + 1, z + 12), RUNE_PLAIN, 2);
        world.setBlockState(new BlockPos(x + 13, y + 1, z + 13), RUNE_PLAIN, 2);
        world.setBlockState(new BlockPos(x + 13, y + 1, z + 14), RUNE_CRACKED, 2);
        world.setBlockState(new BlockPos(x + 13, y + 2, z + 1), RUNE_MOSSY, 2);
        world.setBlockState(new BlockPos(x + 13, y + 2, z + 14), RUNE_MOSSY, 2);
        world.setBlockState(new BlockPos(x + 13, y + 3, z + 1), RUNE_CRACKED, 2);
        world.setBlockState(new BlockPos(x + 13, y + 3, z + 14), PLAIN, 2);
        world.setBlockState(new BlockPos(x + 13, y + 4, z + 1), MOSSY, 2);
        world.setBlockState(new BlockPos(x + 13, y + 4, z + 14), RUNE_MOSSY, 2);
        world.setBlockState(new BlockPos(x + 13, y + 5, z + 1), MOSSY, 2);
        world.setBlockState(new BlockPos(x + 13, y + 5, z + 14), RUNE_MOSSY, 2);
        world.setBlockState(new BlockPos(x + 13, y + 6, z + 1), MOSSY, 2);
        world.setBlockState(new BlockPos(x + 13, y + 6, z + 14), PLAIN, 2);
        world.setBlockState(new BlockPos(x + 13, y + 7, z + 1), PLAIN, 2);
        world.setBlockState(new BlockPos(x + 13, y + 7, z + 14), RUNE_PLAIN, 2);
        world.setBlockState(new BlockPos(x + 13, y + 8, z + 1), RUNE_CRACKED, 2);
        world.setBlockState(new BlockPos(x + 13, y + 8, z + 2), MOSSY, 2);
        world.setBlockState(new BlockPos(x + 13, y + 8, z + 3), PLAIN, 2);
        world.setBlockState(new BlockPos(x + 13, y + 8, z + 4), PLAIN, 2);
        world.setBlockState(new BlockPos(x + 13, y + 8, z + 5), MOSSY, 2);
        world.setBlockState(new BlockPos(x + 13, y + 8, z + 6), MOSSY, 2);
        world.setBlockState(new BlockPos(x + 13, y + 8, z + 7), MOSSY, 2);
        world.setBlockState(new BlockPos(x + 13, y + 8, z + 8), MOSSY, 2);
        world.setBlockState(new BlockPos(x + 13, y + 8, z + 9), PLAIN, 2);
        world.setBlockState(new BlockPos(x + 13, y + 8, z + 10), RUNE_MOSSY, 2);
        world.setBlockState(new BlockPos(x + 13, y + 8, z + 11), RUNE_MOSSY, 2);
        world.setBlockState(new BlockPos(x + 13, y + 8, z + 12), MOSSY, 2);
        world.setBlockState(new BlockPos(x + 13, y + 8, z + 13), CRACKED, 2);
        world.setBlockState(new BlockPos(x + 13, y + 8, z + 14), CRACKED, 2);
        world.setBlockState(new BlockPos(x + 14, y + 1, z + 1), MOSSY, 2);
        world.setBlockState(new BlockPos(x + 14, y + 1, z + 2), RUNE_CRACKED, 2);
        world.setBlockState(new BlockPos(x + 14, y + 1, z + 3), MOSSY, 2);
        world.setBlockState(new BlockPos(x + 14, y + 1, z + 4), CRACKED, 2);
        world.setBlockState(new BlockPos(x + 14, y + 1, z + 5), RUNE_CRACKED, 2);
        world.setBlockState(new BlockPos(x + 14, y + 1, z + 6), PLAIN, 2);
        world.setBlockState(new BlockPos(x + 14, y + 1, z + 7), RUNE_PLAIN, 2);
        world.setBlockState(new BlockPos(x + 14, y + 1, z + 8), MOSSY, 2);
        world.setBlockState(new BlockPos(x + 14, y + 1, z + 9), RUNE_CRACKED, 2);
        world.setBlockState(new BlockPos(x + 14, y + 1, z + 10), RUNE_CRACKED, 2);
        world.setBlockState(new BlockPos(x + 14, y + 1, z + 11), PLAIN, 2);
        world.setBlockState(new BlockPos(x + 14, y + 1, z + 12), RUNE_PLAIN, 2);
        world.setBlockState(new BlockPos(x + 14, y + 1, z + 13), RUNE_MOSSY, 2);
        world.setBlockState(new BlockPos(x + 14, y + 1, z + 14), PLAIN, 2);
        world.setBlockState(new BlockPos(x + 14, y + 2, z + 1), CRACKED, 2);
        world.setBlockState(new BlockPos(x + 14, y + 2, z + 2), RUNE_CRACKED, 2);
        world.setBlockState(new BlockPos(x + 14, y + 2, z + 3), RUNE_MOSSY, 2);
        world.setBlockState(new BlockPos(x + 14, y + 2, z + 4), RUNE_MOSSY, 2);
        world.setBlockState(new BlockPos(x + 14, y + 2, z + 5), CRACKED, 2);
        world.setBlockState(new BlockPos(x + 14, y + 2, z + 10), PLAIN, 2);
        world.setBlockState(new BlockPos(x + 14, y + 2, z + 11), MOSSY, 2);
        world.setBlockState(new BlockPos(x + 14, y + 2, z + 12), CRACKED, 2);
        world.setBlockState(new BlockPos(x + 14, y + 2, z + 13), RUNE_PLAIN, 2);
        world.setBlockState(new BlockPos(x + 14, y + 2, z + 14), PLAIN, 2);
        world.setBlockState(new BlockPos(x + 14, y + 3, z + 1), RUNE_PLAIN, 2);
        world.setBlockState(new BlockPos(x + 14, y + 3, z + 2), RUNE_MOSSY, 2);
        world.setBlockState(new BlockPos(x + 14, y + 3, z + 3), RUNE_CRACKED, 2);
        world.setBlockState(new BlockPos(x + 14, y + 3, z + 4), MOSSY, 2);
        world.setBlockState(new BlockPos(x + 14, y + 3, z + 5), RUNE_MOSSY, 2);
        world.setBlockState(new BlockPos(x + 14, y + 3, z + 10), RUNE_MOSSY, 2);
        world.setBlockState(new BlockPos(x + 14, y + 3, z + 11), PLAIN, 2);
        world.setBlockState(new BlockPos(x + 14, y + 3, z + 12), PLAIN, 2);
        world.setBlockState(new BlockPos(x + 14, y + 3, z + 13), RUNE_PLAIN, 2);
        world.setBlockState(new BlockPos(x + 14, y + 3, z + 14), RUNE_CRACKED, 2);
        world.setBlockState(new BlockPos(x + 14, y + 4, z + 1), PLAIN, 2);
        world.setBlockState(new BlockPos(x + 14, y + 4, z + 2), RUNE_CRACKED, 2);
        world.setBlockState(new BlockPos(x + 14, y + 4, z + 3), PLAIN, 2);
        world.setBlockState(new BlockPos(x + 14, y + 4, z + 4), RUNE_CRACKED, 2);
        world.setBlockState(new BlockPos(x + 14, y + 4, z + 5), RUNE_PLAIN, 2);
        world.setBlockState(new BlockPos(x + 14, y + 4, z + 10), RUNE_PLAIN, 2);
        world.setBlockState(new BlockPos(x + 14, y + 4, z + 11), RUNE_MOSSY, 2);
        world.setBlockState(new BlockPos(x + 14, y + 4, z + 12), RUNE_PLAIN, 2);
        world.setBlockState(new BlockPos(x + 14, y + 4, z + 13), RUNE_CRACKED, 2);
        world.setBlockState(new BlockPos(x + 14, y + 4, z + 14), MOSSY, 2);
        world.setBlockState(new BlockPos(x + 14, y + 5, z + 1), PLAIN, 2);
        world.setBlockState(new BlockPos(x + 14, y + 5, z + 2), PLAIN, 2);
        world.setBlockState(new BlockPos(x + 14, y + 5, z + 3), PLAIN, 2);
        world.setBlockState(new BlockPos(x + 14, y + 5, z + 4), CRACKED, 2);
        world.setBlockState(new BlockPos(x + 14, y + 5, z + 5), RUNE_CRACKED, 2);
        world.setBlockState(new BlockPos(x + 14, y + 5, z + 6), MOSSY, 2);
        world.setBlockState(new BlockPos(x + 14, y + 5, z + 7), MOSSY, 2);
        world.setBlockState(new BlockPos(x + 14, y + 5, z + 8), MOSSY, 2);
        world.setBlockState(new BlockPos(x + 14, y + 5, z + 9), RUNE_PLAIN, 2);
        world.setBlockState(new BlockPos(x + 14, y + 5, z + 10), PLAIN, 2);
        world.setBlockState(new BlockPos(x + 14, y + 5, z + 11), MOSSY, 2);
        world.setBlockState(new BlockPos(x + 14, y + 5, z + 12), PLAIN, 2);
        world.setBlockState(new BlockPos(x + 14, y + 5, z + 13), CRACKED, 2);
        world.setBlockState(new BlockPos(x + 14, y + 5, z + 14), MOSSY, 2);
        world.setBlockState(new BlockPos(x + 14, y + 6, z + 1), MOSSY, 2);
        world.setBlockState(new BlockPos(x + 14, y + 6, z + 2), MOSSY, 2);
        world.setBlockState(new BlockPos(x + 14, y + 6, z + 3), RUNE_PLAIN, 2);
        world.setBlockState(new BlockPos(x + 14, y + 6, z + 4), PLAIN, 2);
        world.setBlockState(new BlockPos(x + 14, y + 6, z + 5), CRACKED, 2);
        world.setBlockState(new BlockPos(x + 14, y + 6, z + 6), RUNE_CRACKED, 2);
        world.setBlockState(new BlockPos(x + 14, y + 6, z + 7), CRACKED, 2);
        world.setBlockState(new BlockPos(x + 14, y + 6, z + 8), CRACKED, 2);
        world.setBlockState(new BlockPos(x + 14, y + 6, z + 9), CRACKED, 2);
        world.setBlockState(new BlockPos(x + 14, y + 6, z + 10), MOSSY, 2);
        world.setBlockState(new BlockPos(x + 14, y + 6, z + 11), RUNE_CRACKED, 2);
        world.setBlockState(new BlockPos(x + 14, y + 6, z + 12), RUNE_PLAIN, 2);
        world.setBlockState(new BlockPos(x + 14, y + 6, z + 13), PLAIN, 2);
        world.setBlockState(new BlockPos(x + 14, y + 6, z + 14), CRACKED, 2);
        world.setBlockState(new BlockPos(x + 14, y + 7, z + 1), CRACKED, 2);
        world.setBlockState(new BlockPos(x + 14, y + 7, z + 2), RUNE_CRACKED, 2);
        world.setBlockState(new BlockPos(x + 14, y + 7, z + 3), RUNE_PLAIN, 2);
        world.setBlockState(new BlockPos(x + 14, y + 7, z + 4), PLAIN, 2);
        world.setBlockState(new BlockPos(x + 14, y + 7, z + 5), RUNE_PLAIN, 2);
        world.setBlockState(new BlockPos(x + 14, y + 7, z + 6), RUNE_PLAIN, 2);
        world.setBlockState(new BlockPos(x + 14, y + 7, z + 7), RUNE_PLAIN, 2);
        world.setBlockState(new BlockPos(x + 14, y + 7, z + 8), MOSSY, 2);
        world.setBlockState(new BlockPos(x + 14, y + 7, z + 9), PLAIN, 2);
        world.setBlockState(new BlockPos(x + 14, y + 7, z + 10), PLAIN, 2);
        world.setBlockState(new BlockPos(x + 14, y + 7, z + 11), RUNE_MOSSY, 2);
        world.setBlockState(new BlockPos(x + 14, y + 7, z + 12), PLAIN, 2);
        world.setBlockState(new BlockPos(x + 14, y + 7, z + 13), MOSSY, 2);
        world.setBlockState(new BlockPos(x + 14, y + 7, z + 14), PLAIN, 2);
        world.setBlockState(new BlockPos(x + 14, y + 8, z + 1), RUNE_MOSSY, 2);
        world.setBlockState(new BlockPos(x + 14, y + 8, z + 2), RUNE_MOSSY, 2);
        world.setBlockState(new BlockPos(x + 14, y + 8, z + 3), RUNE_CRACKED, 2);
        world.setBlockState(new BlockPos(x + 14, y + 8, z + 4), RUNE_CRACKED, 2);
        world.setBlockState(new BlockPos(x + 14, y + 8, z + 5), CRACKED, 2);
        world.setBlockState(new BlockPos(x + 14, y + 8, z + 6), RUNE_PLAIN, 2);
        world.setBlockState(new BlockPos(x + 14, y + 8, z + 7), RUNE_PLAIN, 2);
        world.setBlockState(new BlockPos(x + 14, y + 8, z + 8), RUNE_CRACKED, 2);
        world.setBlockState(new BlockPos(x + 14, y + 8, z + 9), RUNE_PLAIN, 2);
        world.setBlockState(new BlockPos(x + 14, y + 8, z + 10), MOSSY, 2);
        world.setBlockState(new BlockPos(x + 14, y + 8, z + 11), RUNE_CRACKED, 2);
        world.setBlockState(new BlockPos(x + 14, y + 8, z + 12), CRACKED, 2);
        world.setBlockState(new BlockPos(x + 14, y + 8, z + 13), CRACKED, 2);
        world.setBlockState(new BlockPos(x + 14, y + 8, z + 14), RUNE_CRACKED, 2);
        world.setBlockState(new BlockPos(x + 15, y + 1, z + 6), PLAIN, 2);
        world.setBlockState(new BlockPos(x + 15, y + 1, z + 7), CRACKED, 2);
        world.setBlockState(new BlockPos(x + 15, y + 1, z + 8), RUNE_PLAIN, 2);
        world.setBlockState(new BlockPos(x + 15, y + 1, z + 9), RUNE_CRACKED, 2);
        world.setBlockState(new BlockPos(x + 15, y + 2, z + 5), RUNE_PLAIN, 2);
        world.setBlockState(new BlockPos(x + 15, y + 2, z + 6), CRACKED, 2);
        world.setBlockState(new BlockPos(x + 15, y + 2, z + 7), RUNE_MOSSY, 2);
        world.setBlockState(new BlockPos(x + 15, y + 2, z + 8), PLAIN, 2);
        world.setBlockState(new BlockPos(x + 15, y + 2, z + 9), RUNE_CRACKED, 2);
        world.setBlockState(new BlockPos(x + 15, y + 2, z + 10), RUNE_PLAIN, 2);
        world.setBlockState(new BlockPos(x + 15, y + 3, z + 5), RUNIC_LAMP, 2);
        world.setBlockState(new BlockPos(x + 15, y + 3, z + 6), RUNE_PLAIN, 2);
        world.setBlockState(new BlockPos(x + 15, y + 3, z + 7), KEY_STONE, 2);
        world.setBlockState(new BlockPos(x + 15, y + 3, z + 8), KEY_STONE, 2);
        world.setBlockState(new BlockPos(x + 15, y + 3, z + 9), RUNE_MOSSY, 2);
        world.setBlockState(new BlockPos(x + 15, y + 3, z + 10), RUNIC_LAMP, 2);
        world.setBlockState(new BlockPos(x + 15, y + 4, z + 5), RUNE_PLAIN, 2);
        world.setBlockState(new BlockPos(x + 15, y + 4, z + 6), MOSSY, 2);
        world.setBlockState(new BlockPos(x + 15, y + 4, z + 7), RUNE_MOSSY, 2);
        world.setBlockState(new BlockPos(x + 15, y + 4, z + 8), RUNE_MOSSY, 2);
        world.setBlockState(new BlockPos(x + 15, y + 4, z + 9), PLAIN, 2);
        world.setBlockState(new BlockPos(x + 15, y + 4, z + 10), RUNE_PLAIN, 2);
        world.setBlockState(new BlockPos(x + 15, y + 5, z + 6), CRACKED, 2);
        world.setBlockState(new BlockPos(x + 15, y + 5, z + 7), PLAIN, 2);
        world.setBlockState(new BlockPos(x + 15, y + 5, z + 8), PLAIN, 2);
        world.setBlockState(new BlockPos(x + 15, y + 5, z + 9), MOSSY, 2);
    }

}